Workbook

Sheet MRI
A1: Rank | B1: Team | C1: Conference | D1: W | E1: L | F1: MRI
A2: =RANK(F2,F$2:F$352) -> 220 | B2: Abilene Christian | C2: =VLOOKUP(B2,'Team Data'!$A$2:$T$659,19,FALSE()) -> Southland | D2: =VLOOKUP(B2,'Team Data'!$A$2:$T$659,2,FALSE()) -> 16 | E2: =VLOOKUP(B2,'Team Data'!$A$2:$T$659,3,FALSE()) -> 16 | F2: =VLOOKUP(B2,'Team Data'!$A$2:$T$659,20,FALSE()) -> 16.790575
A3: =RANK(F3,F$2:F$352) -> 275 | B3: Air Force | C3: =VLOOKUP(B3,'Team Data'!$A$2:$T$659,19,FALSE()) -> Mountain West | D3: =VLOOKUP(B3,'Team Data'!$A$2:$T$659,2,FALSE()) -> 12 | E3: =VLOOKUP(B3,'Team Data'!$A$2:$T$659,3,FALSE()) -> 19 | F3: =VLOOKUP(B3,'Team Data'!$A$2:$T$659,20,FALSE()) -> -11.066422
A4: =RANK(F4,F$2:F$352) -> 266 | B4: Akron | C4: =VLOOKUP(B4,'Team Data'!$A$2:$T$659,19,FALSE()) -> MAC | D4: =VLOOKUP(B4,'Team Data'!$A$2:$T$659,2,FALSE()) -> 14 | E4: =VLOOKUP(B4,'Team Data'!$A$2:$T$659,3,FALSE()) -> 18 | F4: =VLOOKUP(B4,'Team Data'!$A$2:$T$659,20,FALSE()) -> -5.6445401
A5: =RANK(F5,F$2:F$352) -> 84 | B5: Alabama | C5: =VLOOKUP(B5,'Team Data'!$A$2:$T$659,19,FALSE()) -> SEC | D5: =VLOOKUP(B5,'Team Data'!$A$2:$T$659,2,FALSE()) -> 20 | E5: =VLOOKUP(B5,'Team Data'!$A$2:$T$659,3,FALSE()) -> 16 | F5: =VLOOKUP(B5,'Team Data'!$A$2:$T$659,20,FALSE()) -> 80.71429
A6: =RANK(F6,F$2:F$352) -> 351 | B6: Alabama A&M | C6: =VLOOKUP(B6,'Team Data'!$A$2:$T$659,19,FALSE()) -> SWAC | D6: =VLOOKUP(B6,'Team Data'!$A$2:$T$659,2,FALSE()) -> 3 | E6: =VLOOKUP(B6,'Team Data'!$A$2:$T$659,3,FALSE()) -> 28 | F6: =VLOOKUP(B6,'Team Data'!$A$2:$T$659,20,FALSE()) -> -125.81915
A7: =RANK(F7,F$2:F$352) -> 336 | B7: Alabama State | C7: =VLOOKUP(B7,'Team Data'!$A$2:$T$659,19,FALSE()) -> SWAC | D7: =VLOOKUP(B7,'Team Data'!$A$2:$T$659,2,FALSE()) -> 8 | E7: =VLOOKUP(B7,'Team Data'!$A$2:$T$659,3,FALSE()) -> 23 | F7: =VLOOKUP(B7,'Team Data'!$A$2:$T$659,20,FALSE()) -> -63.644418
A8: =RANK(F8,F$2:F$352) -> 339 | B8: Alcorn State | C8: =VLOOKUP(B8,'Team Data'!$A$2:$T$659,19,FALSE()) -> SWAC | D8: =VLOOKUP(B8,'Team Data'!$A$2:$T$659,2,FALSE()) -> 11 | E8: =VLOOKUP(B8,'Team Data'!$A$2:$T$659,3,FALSE()) -> 21 | F8: =VLOOKUP(B8,'Team Data'!$A$2:$T$659,20,FALSE()) -> -65.776702
A9: =RANK(F9,F$2:F$352) -> 326 | B9: American University | C9: =VLOOKUP(B9,'Team Data'!$A$2:$T$659,19,FALSE()) -> Patriot | D9: =VLOOKUP(B9,'Team Data'!$A$2:$T$659,2,FALSE()) -> 6 | E9: =VLOOKUP(B9,'Team Data'!$A$2:$T$659,3,FALSE()) -> 24 | F9: =VLOOKUP(B9,'Team Data'!$A$2:$T$659,20,FALSE()) -> -46.848905
A10: =RANK(F10,F$2:F$352) -> 214 | B10: App State | C10: =VLOOKUP(B10,'Team Data'!$A$2:$T$659,19,FALSE()) -> Sun Belt | D10: =VLOOKUP(B10,'Team Data'!$A$2:$T$659,2,FALSE()) -> 15 | E10: =VLOOKUP(B10,'Team Data'!$A$2:$T$659,3,FALSE()) -> 18 | F10: =VLOOKUP(B10,'Team Data'!$A$2:$T$659,20,FALSE()) -> 21.192514
A11: =RANK(F11,F$2:F$352) -> 24 | B11: Arizona | C11: =VLOOKUP(B11,'Team Data'!$A$2:$T$659,19,FALSE()) -> Pac-12 | D11: =VLOOKUP(B11,'Team Data'!$A$2:$T$659,2,FALSE()) -> 26 | E11: =VLOOKUP(B11,'Team Data'!$A$2:$T$659,3,FALSE()) -> 8 | F11: =VLOOKUP(B11,'Team Data'!$A$2:$T$659,20,FALSE()) -> 136.06536
A12: =RANK(F12,F$2:F$352) -> 52 | B12: Arizona State | C12: =VLOOKUP(B12,'Team Data'!$A$2:$T$659,19,FALSE()) -> Pac-12 | D12: =VLOOKUP(B12,'Team Data'!$A$2:$T$659,2,FALSE()) -> 20 | E12: =VLOOKUP(B12,'Team Data'!$A$2:$T$659,3,FALSE()) -> 12 | F12: =VLOOKUP(B12,'Team Data'!$A$2:$T$659,20,FALSE()) -> 105.7004
A13: =RANK(F13,F$2:F$352) -> 55 | B13: Arkansas | C13: =VLOOKUP(B13,'Team Data'!$A$2:$T$659,19,FALSE()) -> SEC | D13: =VLOOKUP(B13,'Team Data'!$A$2:$T$659,2,FALSE()) -> 23 | E13: =VLOOKUP(B13,'Team Data'!$A$2:$T$659,3,FALSE()) -> 12 | F13: =VLOOKUP(B13,'Team Data'!$A$2:$T$659,20,FALSE()) -> 102.95742
... A352: =RANK(F352,F$2:F$352) -> 323 | B352: Youngstown State | C352: =VLOOKUP(B352,'Team Data'!$A$2:$T$659,19,FALSE()) -> Horizon | D352: =VLOOKUP(B352,'Team Data'!$A$2:$T$659,2,FALSE()) -> 8 | E352: =VLOOKUP(B352,'Team Data'!$A$2:$T$659,3,FALSE()) -> 24 | F352: =VLOOKUP(B352,'Team Data'!$A$2:$T$659,20,FALSE()) -> -42.199477

Sheet About
A1: MRI 2017–18
A3: 5968 games, 351 D1 teams.
A5: MISSING BOX SCORES
A6: 52 of these 5968 games have a score but no rebound or
A7: turnover counts in the source data. Their Reb and TO cells are blank
A8: rather than zero, and column Y of Team Data counts the games that do
A9: have counts - that is what RDPG and TODPG divide by, so a missing box
A10: score costs a team nothing but the statistics it never reported.
A12: WHAT IS LIVE
A13: Games, Team Data and MRI carry the original formulas. Correct a score on
A14: the Games sheet and the whole season re-rates, exactly as the 2003-2019
A15: workbooks did. Only columns A-J and Date are data; K through T are formulas.
... A29: Generated by github.com/bmiraski/mri_ratings

Sheet Games
A1: Team1 | B1: Team2 | C1: Pnt1 | D1: Pnt2 | E1: Reb1 | F1: Reb2 | G1: TO1 | H1: TO2 | I1: WT1 | J1: WT2 | K1: T1W | L1: T1L | M1: T2W | N1: T2L | O1: T1OW | P1: T1OL | Q1: T2OW | R1: T2OL | S1: T1Point | T1: T2Point | U1: Date
A2: Spring Arbor | B2: Eastern Michigan | C2: 60 | D2: 92 | E2: 38 | F2: 37 | G2: 24 | H2: 8 | I2: 0 | J2: 1 | K2: =VLOOKUP(A2,'Team Data'!$A$1:$E$659,2,FALSE()) -> 0 | L2: =VLOOKUP(A2,'Team Data'!$A$1:$E$659,3,FALSE()) -> 1 | M2: =VLOOKUP(B2,'Team Data'!$A$1:$E$659,2,FALSE()) -> 22 | N2: =VLOOKUP(B2,'Team Data'!$A$1:$E$659,3,FALSE()) -> 13 | O2: =VLOOKUP(A2,'Team Data'!$A$1:$E$659,4,FALSE()) -> 22 | P2: =VLOOKUP(A2,'Team Data'!$A$1:$E$659,5,FALSE()) -> 13 | Q2: =VLOOKUP(B2,'Team Data'!$A$1:$E$659,4,FALSE()) -> 536 | R2: =VLOOKUP(B2,'Team Data'!$A$1:$E$659,5,FALSE()) -> 497 | S2: =IF(I2=1,(MIN(30,(C2-D2)))*(M2/(M2+N2))*(Q2/(Q2+R2)),(MAX(-30,(C2-D2)))*(N2/(M2+N2))*(R2/(R2+Q2))) -> -5.3610842 | T2: =IF(J2=1,(MIN(30,(D2-C2)))*(K2/(K2+L2))*(O2/(O2+P2)),(MAX(-30,(D2-C2)))*(L2/(K2+L2))*(P2/(P2+O2))) -> 0 | U2: 43049
A3: Webber International | B3: Stetson | C3: 89 | D3: 98 | E3: 39 | F3: 45 | G3: 15 | H3: 13 | I3: 0 | J3: 1 | K3: =VLOOKUP(A3,'Team Data'!$A$1:$E$659,2,FALSE()) -> 0 | L3: =VLOOKUP(A3,'Team Data'!$A$1:$E$659,3,FALSE()) -> 4 | M3: =VLOOKUP(B3,'Team Data'!$A$1:$E$659,2,FALSE()) -> 12 | N3: =VLOOKUP(B3,'Team Data'!$A$1:$E$659,3,FALSE()) -> 20 | O3: =VLOOKUP(A3,'Team Data'!$A$1:$E$659,4,FALSE()) -> 62 | P3: =VLOOKUP(A3,'Team Data'!$A$1:$E$659,5,FALSE()) -> 69 | Q3: =VLOOKUP(B3,'Team Data'!$A$1:$E$659,4,FALSE()) -> 427 | R3: =VLOOKUP(B3,'Team Data'!$A$1:$E$659,5,FALSE()) -> 489 | S3: =IF(I3=1,(MIN(30,(C3-D3)))*(M3/(M3+N3))*(Q3/(Q3+R3)),(MAX(-30,(C3-D3)))*(N3/(M3+N3))*(R3/(R3+Q3))) -> -3.0028657 | T3: =IF(J3=1,(MIN(30,(D3-C3)))*(K3/(K3+L3))*(O3/(O3+P3)),(MAX(-30,(D3-C3)))*(L3/(K3+L3))*(P3/(P3+O3))) -> 0 | U3: 43049
A4: Trevecca Nazarene | B4: Middle Tennessee | C4: 52 | D4: 104 | E4: 27 | F4: 40 | G4: 22 | H4: 8 | I4: 0 | J4: 1 | K4: =VLOOKUP(A4,'Team Data'!$A$1:$E$659,2,FALSE()) -> 0 | L4: =VLOOKUP(A4,'Team Data'!$A$1:$E$659,3,FALSE()) -> 1 | M4: =VLOOKUP(B4,'Team Data'!$A$1:$E$659,2,FALSE()) -> 25 | N4: =VLOOKUP(B4,'Team Data'!$A$1:$E$659,3,FALSE()) -> 8 | O4: =VLOOKUP(A4,'Team Data'!$A$1:$E$659,4,FALSE()) -> 25 | P4: =VLOOKUP(A4,'Team Data'!$A$1:$E$659,5,FALSE()) -> 8 | Q4: =VLOOKUP(B4,'Team Data'!$A$1:$E$659,4,FALSE()) -> 610 | R4: =VLOOKUP(B4,'Team Data'!$A$1:$E$659,5,FALSE()) -> 461 | S4: =IF(I4=1,(MIN(30,(C4-D4)))*(M4/(M4+N4))*(Q4/(Q4+R4)),(MAX(-30,(C4-D4)))*(N4/(M4+N4))*(R4/(R4+Q4))) -> -3.1304643 | T4: =IF(J4=1,(MIN(30,(D4-C4)))*(K4/(K4+L4))*(O4/(O4+P4)),(MAX(-30,(D4-C4)))*(L4/(K4+L4))*(P4/(P4+O4))) -> 0 | U4: 43049
A5: Lamar | B5: Tulsa | C5: 74 | D5: 67 | E5: 42 | F5: 28 | G5: 16 | H5: 15 | I5: 1 | J5: 0 | K5: =VLOOKUP(A5,'Team Data'!$A$1:$E$659,2,FALSE()) -> 19 | L5: =VLOOKUP(A5,'Team Data'!$A$1:$E$659,3,FALSE()) -> 14 | M5: =VLOOKUP(B5,'Team Data'!$A$1:$E$659,2,FALSE()) -> 19 | N5: =VLOOKUP(B5,'Team Data'!$A$1:$E$659,3,FALSE()) -> 12 | O5: =VLOOKUP(A5,'Team Data'!$A$1:$E$659,4,FALSE()) -> 451 | P5: =VLOOKUP(A5,'Team Data'!$A$1:$E$659,5,FALSE()) -> 488 | Q5: =VLOOKUP(B5,'Team Data'!$A$1:$E$659,4,FALSE()) -> 534 | R5: =VLOOKUP(B5,'Team Data'!$A$1:$E$659,5,FALSE()) -> 472 | S5: =IF(I5=1,(MIN(30,(C5-D5)))*(M5/(M5+N5))*(Q5/(Q5+R5)),(MAX(-30,(C5-D5)))*(N5/(M5+N5))*(R5/(R5+Q5))) -> 2.277368 | T5: =IF(J5=1,(MIN(30,(D5-C5)))*(K5/(K5+L5))*(O5/(O5+P5)),(MAX(-30,(D5-C5)))*(L5/(K5+L5))*(P5/(P5+O5))) -> -1.5433569 | U5: 43049
A6: Central Arkansas | B6: Baylor | C6: 66 | D6: 107 | E6: 21 | F6: 42 | G6: 12 | H6: 16 | I6: 0 | J6: 1 | K6: =VLOOKUP(A6,'Team Data'!$A$1:$E$659,2,FALSE()) -> 18 | L6: =VLOOKUP(A6,'Team Data'!$A$1:$E$659,3,FALSE()) -> 17 | M6: =VLOOKUP(B6,'Team Data'!$A$1:$E$659,2,FALSE()) -> 18 | N6: =VLOOKUP(B6,'Team Data'!$A$1:$E$659,3,FALSE()) -> 15 | O6: =VLOOKUP(A6,'Team Data'!$A$1:$E$659,4,FALSE()) -> 546 | P6: =VLOOKUP(A6,'Team Data'!$A$1:$E$659,5,FALSE()) -> 561 | Q6: =VLOOKUP(B6,'Team Data'!$A$1:$E$659,4,FALSE()) -> 668 | R6: =VLOOKUP(B6,'Team Data'!$A$1:$E$659,5,FALSE()) -> 423 | S6: =IF(I6=1,(MIN(30,(C6-D6)))*(M6/(M6+N6))*(Q6/(Q6+R6)),(MAX(-30,(C6-D6)))*(N6/(M6+N6))*(R6/(R6+Q6))) -> -5.2870594 | T6: =IF(J6=1,(MIN(30,(D6-C6)))*(K6/(K6+L6))*(O6/(O6+P6)),(MAX(-30,(D6-C6)))*(L6/(K6+L6))*(P6/(P6+O6))) -> 7.6097561 | U6: 43049
A7: Wheelock College | B7: New Hampshire | C7: 39 | D7: 95 | E7: 28 | F7: 49 | G7: 23 | H7: 12 | I7: 0 | J7: 1 | K7: =VLOOKUP(A7,'Team Data'!$A$1:$E$659,2,FALSE()) -> 0 | L7: =VLOOKUP(A7,'Team Data'!$A$1:$E$659,3,FALSE()) -> 1 | M7: =VLOOKUP(B7,'Team Data'!$A$1:$E$659,2,FALSE()) -> 10 | N7: =VLOOKUP(B7,'Team Data'!$A$1:$E$659,3,FALSE()) -> 21 | O7: =VLOOKUP(A7,'Team Data'!$A$1:$E$659,4,FALSE()) -> 10 | P7: =VLOOKUP(A7,'Team Data'!$A$1:$E$659,5,FALSE()) -> 21 | Q7: =VLOOKUP(B7,'Team Data'!$A$1:$E$659,4,FALSE()) -> 463 | R7: =VLOOKUP(B7,'Team Data'!$A$1:$E$659,5,FALSE()) -> 473 | S7: =IF(I7=1,(MIN(30,(C7-D7)))*(M7/(M7+N7))*(Q7/(Q7+R7)),(MAX(-30,(C7-D7)))*(N7/(M7+N7))*(R7/(R7+Q7))) -> -10.269851 | T7: =IF(J7=1,(MIN(30,(D7-C7)))*(K7/(K7+L7))*(O7/(O7+P7)),(MAX(-30,(D7-C7)))*(L7/(K7+L7))*(P7/(P7+O7))) -> 0 | U7: 43049
A8: Millsaps | B8: Jackson State | C8: 46 | D8: 84 | E8: 32 | F8: 39 | G8: 31 | H8: 14 | I8: 0 | J8: 1 | K8: =VLOOKUP(A8,'Team Data'!$A$1:$E$659,2,FALSE()) -> 0 | L8: =VLOOKUP(A8,'Team Data'!$A$1:$E$659,3,FALSE()) -> 2 | M8: =VLOOKUP(B8,'Team Data'!$A$1:$E$659,2,FALSE()) -> 12 | N8: =VLOOKUP(B8,'Team Data'!$A$1:$E$659,3,FALSE()) -> 20 | O8: =VLOOKUP(A8,'Team Data'!$A$1:$E$659,4,FALSE()) -> 28 | P8: =VLOOKUP(A8,'Team Data'!$A$1:$E$659,5,FALSE()) -> 36 | Q8: =VLOOKUP(B8,'Team Data'!$A$1:$E$659,4,FALSE()) -> 419 | R8: =VLOOKUP(B8,'Team Data'!$A$1:$E$659,5,FALSE()) -> 571 | S8: =IF(I8=1,(MIN(30,(C8-D8)))*(M8/(M8+N8))*(Q8/(Q8+R8)),(MAX(-30,(C8-D8)))*(N8/(M8+N8))*(R8/(R8+Q8))) -> -10.814394 | T8: =IF(J8=1,(MIN(30,(D8-C8)))*(K8/(K8+L8))*(O8/(O8+P8)),(MAX(-30,(D8-C8)))*(L8/(K8+L8))*(P8/(P8+O8))) -> 0 | U8: 43049
A9: Oglethorpe | B9: The Citadel | C9: 73 | D9: 109 | E9: 44 | F9: 50 | G9: 25 | H9: 16 | I9: 0 | J9: 1 | K9: =VLOOKUP(A9,'Team Data'!$A$1:$E$659,2,FALSE()) -> 0 | L9: =VLOOKUP(A9,'Team Data'!$A$1:$E$659,3,FALSE()) -> 1 | M9: =VLOOKUP(B9,'Team Data'!$A$1:$E$659,2,FALSE()) -> 11 | N9: =VLOOKUP(B9,'Team Data'!$A$1:$E$659,3,FALSE()) -> 21 | O9: =VLOOKUP(A9,'Team Data'!$A$1:$E$659,4,FALSE()) -> 11 | P9: =VLOOKUP(A9,'Team Data'!$A$1:$E$659,5,FALSE()) -> 21 | Q9: =VLOOKUP(B9,'Team Data'!$A$1:$E$659,4,FALSE()) -> 511 | R9: =VLOOKUP(B9,'Team Data'!$A$1:$E$659,5,FALSE()) -> 448 | S9: =IF(I9=1,(MIN(30,(C9-D9)))*(M9/(M9+N9))*(Q9/(Q9+R9)),(MAX(-30,(C9-D9)))*(N9/(M9+N9))*(R9/(R9+Q9))) -> -9.1970803 | T9: =IF(J9=1,(MIN(30,(D9-C9)))*(K9/(K9+L9))*(O9/(O9+P9)),(MAX(-30,(D9-C9)))*(L9/(K9+L9))*(P9/(P9+O9))) -> 0 | U9: 43049
A10: Campbell | B10: Penn State | C10: 75 | D10: 86 | E10: 37 | F10: 44 | G10: 18 | H10: 14 | I10: 0 | J10: 1 | K10: =VLOOKUP(A10,'Team Data'!$A$1:$E$659,2,FALSE()) -> 18 | L10: =VLOOKUP(A10,'Team Data'!$A$1:$E$659,3,FALSE()) -> 16 | M10: =VLOOKUP(B10,'Team Data'!$A$1:$E$659,2,FALSE()) -> 26 | N10: =VLOOKUP(B10,'Team Data'!$A$1:$E$659,3,FALSE()) -> 12 | O10: =VLOOKUP(A10,'Team Data'!$A$1:$E$659,4,FALSE()) -> 493 | P10: =VLOOKUP(A10,'Team Data'!$A$1:$E$659,5,FALSE()) -> 541 | Q10: =VLOOKUP(B10,'Team Data'!$A$1:$E$659,4,FALSE()) -> 700 | R10: =VLOOKUP(B10,'Team Data'!$A$1:$E$659,5,FALSE()) -> 549 | S10: =IF(I10=1,(MIN(30,(C10-D10)))*(M10/(M10+N10))*(Q10/(Q10+R10)),(MAX(-30,(C10-D10)))*(N10/(M10+N10))*(R10/(R10+Q10))) -> -1.5268636 | T10: =IF(J10=1,(MIN(30,(D10-C10)))*(K10/(K10+L10))*(O10/(O10+P10)),(MAX(-30,(D10-C10)))*(L10/(K10+L10))*(P10/(P10+O10))) -> 2.7765957 | U10: 43049
A11: Siena Heights | B11: Central Michigan | C11: 48 | D11: 108 | E11: 30 | F11: 45 | G11: 29 | H11: 11 | I11: 0 | J11: 1 | K11: =VLOOKUP(A11,'Team Data'!$A$1:$E$659,2,FALSE()) -> 0 | L11: =VLOOKUP(A11,'Team Data'!$A$1:$E$659,3,FALSE()) -> 3 | M11: =VLOOKUP(B11,'Team Data'!$A$1:$E$659,2,FALSE()) -> 21 | N11: =VLOOKUP(B11,'Team Data'!$A$1:$E$659,3,FALSE()) -> 15 | O11: =VLOOKUP(A11,'Team Data'!$A$1:$E$659,4,FALSE()) -> 46 | P11: =VLOOKUP(A11,'Team Data'!$A$1:$E$659,5,FALSE()) -> 54 | Q11: =VLOOKUP(B11,'Team Data'!$A$1:$E$659,4,FALSE()) -> 577 | R11: =VLOOKUP(B11,'Team Data'!$A$1:$E$659,5,FALSE()) -> 521 | S11: =IF(I11=1,(MIN(30,(C11-D11)))*(M11/(M11+N11))*(Q11/(Q11+R11)),(MAX(-30,(C11-D11)))*(N11/(M11+N11))*(R11/(R11+Q11))) -> -5.9312386 | T11: =IF(J11=1,(MIN(30,(D11-C11)))*(K11/(K11+L11))*(O11/(O11+P11)),(MAX(-30,(D11-C11)))*(L11/(K11+L11))*(P11/(P11+O11))) -> 0 | U11: 43049
A12: Walla Walla | B12: Eastern Washington | C12: 61 | D12: 82 | E12: 33 | F12: 45 | G12: 16 | H12: 10 | I12: 0 | J12: 1 | K12: =VLOOKUP(A12,'Team Data'!$A$1:$E$659,2,FALSE()) -> 0 | L12: =VLOOKUP(A12,'Team Data'!$A$1:$E$659,3,FALSE()) -> 2 | M12: =VLOOKUP(B12,'Team Data'!$A$1:$E$659,2,FALSE()) -> 20 | N12: =VLOOKUP(B12,'Team Data'!$A$1:$E$659,3,FALSE()) -> 15 | O12: =VLOOKUP(A12,'Team Data'!$A$1:$E$659,4,FALSE()) -> 30 | P12: =VLOOKUP(A12,'Team Data'!$A$1:$E$659,5,FALSE()) -> 37 | Q12: =VLOOKUP(B12,'Team Data'!$A$1:$E$659,4,FALSE()) -> 577 | R12: =VLOOKUP(B12,'Team Data'!$A$1:$E$659,5,FALSE()) -> 520 | S12: =IF(I12=1,(MIN(30,(C12-D12)))*(M12/(M12+N12))*(Q12/(Q12+R12)),(MAX(-30,(C12-D12)))*(N12/(M12+N12))*(R12/(R12+Q12))) -> -4.2661805 | T12: =IF(J12=1,(MIN(30,(D12-C12)))*(K12/(K12+L12))*(O12/(O12+P12)),(MAX(-30,(D12-C12)))*(L12/(K12+L12))*(P12/(P12+O12))) -> 0 | U12: 43049
A13: Bridgewater College (VA) | B13: James Madison | C13: 50 | D13: 80 | E13: 30 | F13: 53 | G13: 19 | H13: 20 | I13: 0 | J13: 1 | K13: =VLOOKUP(A13,'Team Data'!$A$1:$E$659,2,FALSE()) -> 0 | L13: =VLOOKUP(A13,'Team Data'!$A$1:$E$659,3,FALSE()) -> 2 | M13: =VLOOKUP(B13,'Team Data'!$A$1:$E$659,2,FALSE()) -> 10 | N13: =VLOOKUP(B13,'Team Data'!$A$1:$E$659,3,FALSE()) -> 22 | O13: =VLOOKUP(A13,'Team Data'!$A$1:$E$659,4,FALSE()) -> 25 | P13: =VLOOKUP(A13,'Team Data'!$A$1:$E$659,5,FALSE()) -> 40 | Q13: =VLOOKUP(B13,'Team Data'!$A$1:$E$659,4,FALSE()) -> 532 | R13: =VLOOKUP(B13,'Team Data'!$A$1:$E$659,5,FALSE()) -> 476 | S13: =IF(I13=1,(MIN(30,(C13-D13)))*(M13/(M13+N13))*(Q13/(Q13+R13)),(MAX(-30,(C13-D13)))*(N13/(M13+N13))*(R13/(R13+Q13))) -> -9.7395833 | T13: =IF(J13=1,(MIN(30,(D13-C13)))*(K13/(K13+L13))*(O13/(O13+P13)),(MAX(-30,(D13-C13)))*(L13/(K13+L13))*(P13/(P13+O13))) -> 0 | U13: 43049
... A523: Lakeland | B523: Green Bay | C523: 27 | D523: 98 | E523: 32 | F523: 71 | G523: 8 | H523: 13 | I523: 0 | J523: 1 | K523: =VLOOKUP(A523,'Team Data'!$A$1:$E$659,2,FALSE()) -> 0 | L523: =VLOOKUP(A523,'Team Data'!$A$1:$E$659,3,FALSE()) -> 1 | M523: =VLOOKUP(B523,'Team Data'!$A$1:$E$659,2,FALSE()) -> 13 | N523: =VLOOKUP(B523,'Team Data'!$A$1:$E$659,3,FALSE()) -> 20 | O523: =VLOOKUP(A523,'Team Data'!$A$1:$E$659,4,FALSE()) -> 13 | P523: =VLOOKUP(A523,'Team Data'!$A$1:$E$659,5,FALSE()) -> 20 | Q523: =VLOOKUP(B523,'Team Data'!$A$1:$E$659,4,FALSE()) -> 474 | R523: =VLOOKUP(B523,'Team Data'!$A$1:$E$659,5,FALSE()) -> 521 | S523: =IF(I523=1,(MIN(30,(C523-D523)))*(M523/(M523+N523))*(Q523/(Q523+R523)),(MAX(-30,(C523-D523)))*(N523/(M523+N523))*(R523/(R523+Q523))) -> -9.5203289 | T523: =IF(J523=1,(MIN(30,(D523-C523)))*(K523/(K523+L523))*(O523/(O523+P523)),(MAX(-30,(D523-C523)))*(L523/(K523+L523))*(P523/(P523+O523))) -> 0 | U523: 43057
A524: Long Island University | B524: Miami (OH) | C524: 74 | D524: 78 | I524: 0 | J524: 1 | K524: =VLOOKUP(A524,'Team Data'!$A$1:$E$659,2,FALSE()) -> 18 | L524: =VLOOKUP(A524,'Team Data'!$A$1:$E$659,3,FALSE()) -> 17 | M524: =VLOOKUP(B524,'Team Data'!$A$1:$E$659,2,FALSE()) -> 16 | N524: =VLOOKUP(B524,'Team Data'!$A$1:$E$659,3,FALSE()) -> 18 | O524: =VLOOKUP(A524,'Team Data'!$A$1:$E$659,4,FALSE()) -> 497 | P524: =VLOOKUP(A524,'Team Data'!$A$1:$E$659,5,FALSE()) -> 580 | Q524: =VLOOKUP(B524,'Team Data'!$A$1:$E$659,4,FALSE()) -> 575 | R524: =VLOOKUP(B524,'Team Data'!$A$1:$E$659,5,FALSE()) -> 481 | S524: =IF(I524=1,(MIN(30,(C524-D524)))*(M524/(M524+N524))*(Q524/(Q524+R524)),(MAX(-30,(C524-D524)))*(N524/(M524+N524))*(R524/(R524+Q524))) -> -0.96457219 | T524: =IF(J524=1,(MIN(30,(D524-C524)))*(K524/(K524+L524))*(O524/(O524+P524)),(MAX(-30,(D524-C524)))*(L524/(K524+L524))*(P524/(P524+O524))) -> 0.94930362 | U524: 43057
A525: IU Indianapolis | B525: Eastern Illinois | C525: 79 | D525: 80 | E525: 29 | F525: 26 | G525: 15 | H525: 10 | I525: 0 | J525: 1 | K525: =VLOOKUP(A525,'Team Data'!$A$1:$E$659,2,FALSE()) -> 11 | L525: =VLOOKUP(A525,'Team Data'!$A$1:$E$659,3,FALSE()) -> 19 | M525: =VLOOKUP(B525,'Team Data'!$A$1:$E$659,2,FALSE()) -> 12 | N525: =VLOOKUP(B525,'Team Data'!$A$1:$E$659,3,FALSE()) -> 19 | O525: =VLOOKUP(A525,'Team Data'!$A$1:$E$659,4,FALSE()) -> 459 | P525: =VLOOKUP(A525,'Team Data'!$A$1:$E$659,5,FALSE()) -> 467 | Q525: =VLOOKUP(B525,'Team Data'!$A$1:$E$659,4,FALSE()) -> 475 | R525: =VLOOKUP(B525,'Team Data'!$A$1:$E$659,5,FALSE()) -> 446 | S525: =IF(I525=1,(MIN(30,(C525-D525)))*(M525/(M525+N525))*(Q525/(Q525+R525)),(MAX(-30,(C525-D525)))*(N525/(M525+N525))*(R525/(R525+Q525))) -> -0.29680221 | T525: =IF(J525=1,(MIN(30,(D525-C525)))*(K525/(K525+L525))*(O525/(O525+P525)),(MAX(-30,(D525-C525)))*(L525/(K525+L525))*(P525/(P525+O525))) -> 0.18174946 | U525: 43057
A526: Drake | B526: Wake Forest | C526: 77 | D526: 74 | E526: 37 | F526: 33 | G526: 12 | H526: 12 | I526: 1 | J526: 0 | K526: =VLOOKUP(A526,'Team Data'!$A$1:$E$659,2,FALSE()) -> 17 | L526: =VLOOKUP(A526,'Team Data'!$A$1:$E$659,3,FALSE()) -> 17 | M526: =VLOOKUP(B526,'Team Data'!$A$1:$E$659,2,FALSE()) -> 11 | N526: =VLOOKUP(B526,'Team Data'!$A$1:$E$659,3,FALSE()) -> 20 | O526: =VLOOKUP(A526,'Team Data'!$A$1:$E$659,4,FALSE()) -> 569 | P526: =VLOOKUP(A526,'Team Data'!$A$1:$E$659,5,FALSE()) -> 514 | Q526: =VLOOKUP(B526,'Team Data'!$A$1:$E$659,4,FALSE()) -> 617 | R526: =VLOOKUP(B526,'Team Data'!$A$1:$E$659,5,FALSE()) -> 430 | S526: =IF(I526=1,(MIN(30,(C526-D526)))*(M526/(M526+N526))*(Q526/(Q526+R526)),(MAX(-30,(C526-D526)))*(N526/(M526+N526))*(R526/(R526+Q526))) -> 0.6273223 | T526: =IF(J526=1,(MIN(30,(D526-C526)))*(K526/(K526+L526))*(O526/(O526+P526)),(MAX(-30,(D526-C526)))*(L526/(K526+L526))*(P526/(P526+O526))) -> -0.71191136 | U526: 43057
A527: DePaul | B527: Illinois | C527: 73 | D527: 82 | E527: 36 | F527: 38 | G527: 17 | H527: 18 | I527: 0 | J527: 1 | K527: =VLOOKUP(A527,'Team Data'!$A$1:$E$659,2,FALSE()) -> 11 | L527: =VLOOKUP(A527,'Team Data'!$A$1:$E$659,3,FALSE()) -> 20 | M527: =VLOOKUP(B527,'Team Data'!$A$1:$E$659,2,FALSE()) -> 14 | N527: =VLOOKUP(B527,'Team Data'!$A$1:$E$659,3,FALSE()) -> 18 | O527: =VLOOKUP(A527,'Team Data'!$A$1:$E$659,4,FALSE()) -> 590 | P527: =VLOOKUP(A527,'Team Data'!$A$1:$E$659,5,FALSE()) -> 446 | Q527: =VLOOKUP(B527,'Team Data'!$A$1:$E$659,4,FALSE()) -> 590 | R527: =VLOOKUP(B527,'Team Data'!$A$1:$E$659,5,FALSE()) -> 445 | S527: =IF(I527=1,(MIN(30,(C527-D527)))*(M527/(M527+N527))*(Q527/(Q527+R527)),(MAX(-30,(C527-D527)))*(N527/(M527+N527))*(R527/(R527+Q527))) -> -2.1766304 | T527: =IF(J527=1,(MIN(30,(D527-C527)))*(K527/(K527+L527))*(O527/(O527+P527)),(MAX(-30,(D527-C527)))*(L527/(K527+L527))*(P527/(P527+O527))) -> 1.8187196 | U527: 43057
A528: New Mexico | B528: New Mexico State | C528: 56 | D528: 75 | E528: 25 | F528: 50 | G528: 17 | H528: 14 | I528: 0 | J528: 1 | K528: =VLOOKUP(A528,'Team Data'!$A$1:$E$659,2,FALSE()) -> 19 | L528: =VLOOKUP(A528,'Team Data'!$A$1:$E$659,3,FALSE()) -> 15 | M528: =VLOOKUP(B528,'Team Data'!$A$1:$E$659,2,FALSE()) -> 28 | N528: =VLOOKUP(B528,'Team Data'!$A$1:$E$659,3,FALSE()) -> 6 | O528: =VLOOKUP(A528,'Team Data'!$A$1:$E$659,4,FALSE()) -> 580 | P528: =VLOOKUP(A528,'Team Data'!$A$1:$E$659,5,FALSE()) -> 491 | Q528: =VLOOKUP(B528,'Team Data'!$A$1:$E$659,4,FALSE()) -> 515 | R528: =VLOOKUP(B528,'Team Data'!$A$1:$E$659,5,FALSE()) -> 512 | S528: =IF(I528=1,(MIN(30,(C528-D528)))*(M528/(M528+N528))*(Q528/(Q528+R528)),(MAX(-30,(C528-D528)))*(N528/(M528+N528))*(R528/(R528+Q528))) -> -1.6715734 | T528: =IF(J528=1,(MIN(30,(D528-C528)))*(K528/(K528+L528))*(O528/(O528+P528)),(MAX(-30,(D528-C528)))*(L528/(K528+L528))*(P528/(P528+O528))) -> 5.7499863 | U528: 43057
A529: UC Irvine | B529: Kansas State | C529: 49 | D529: 71 | E529: 39 | F529: 37 | G529: 17 | H529: 8 | I529: 0 | J529: 1 | K529: =VLOOKUP(A529,'Team Data'!$A$1:$E$659,2,FALSE()) -> 18 | L529: =VLOOKUP(A529,'Team Data'!$A$1:$E$659,3,FALSE()) -> 17 | M529: =VLOOKUP(B529,'Team Data'!$A$1:$E$659,2,FALSE()) -> 25 | N529: =VLOOKUP(B529,'Team Data'!$A$1:$E$659,3,FALSE()) -> 12 | O529: =VLOOKUP(A529,'Team Data'!$A$1:$E$659,4,FALSE()) -> 605 | P529: =VLOOKUP(A529,'Team Data'!$A$1:$E$659,5,FALSE()) -> 465 | Q529: =VLOOKUP(B529,'Team Data'!$A$1:$E$659,4,FALSE()) -> 699 | R529: =VLOOKUP(B529,'Team Data'!$A$1:$E$659,5,FALSE()) -> 540 | S529: =IF(I529=1,(MIN(30,(C529-D529)))*(M529/(M529+N529))*(Q529/(Q529+R529)),(MAX(-30,(C529-D529)))*(N529/(M529+N529))*(R529/(R529+Q529))) -> -3.1097441 | T529: =IF(J529=1,(MIN(30,(D529-C529)))*(K529/(K529+L529))*(O529/(O529+P529)),(MAX(-30,(D529-C529)))*(L529/(K529+L529))*(P529/(P529+O529))) -> 6.3973298 | U529: 43057
A530: Alcorn State | B530: Baylor | C530: 61 | D530: 78 | E530: 27 | F530: 49 | G530: 12 | H530: 10 | I530: 0 | J530: 1 | K530: =VLOOKUP(A530,'Team Data'!$A$1:$E$659,2,FALSE()) -> 11 | L530: =VLOOKUP(A530,'Team Data'!$A$1:$E$659,3,FALSE()) -> 21 | M530: =VLOOKUP(B530,'Team Data'!$A$1:$E$659,2,FALSE()) -> 18 | N530: =VLOOKUP(B530,'Team Data'!$A$1:$E$659,3,FALSE()) -> 15 | O530: =VLOOKUP(A530,'Team Data'!$A$1:$E$659,4,FALSE()) -> 370 | P530: =VLOOKUP(A530,'Team Data'!$A$1:$E$659,5,FALSE()) -> 552 | Q530: =VLOOKUP(B530,'Team Data'!$A$1:$E$659,4,FALSE()) -> 668 | R530: =VLOOKUP(B530,'Team Data'!$A$1:$E$659,5,FALSE()) -> 423 | S530: =IF(I530=1,(MIN(30,(C530-D530)))*(M530/(M530+N530))*(Q530/(Q530+R530)),(MAX(-30,(C530-D530)))*(N530/(M530+N530))*(R530/(R530+Q530))) -> -2.9960003 | T530: =IF(J530=1,(MIN(30,(D530-C530)))*(K530/(K530+L530))*(O530/(O530+P530)),(MAX(-30,(D530-C530)))*(L530/(K530+L530))*(P530/(P530+O530))) -> 2.3451057 | U530: 43057
A531: Concordia-St. Paul | B531: Milwaukee | C531: 69 | D531: 55 | E531: 37 | F531: 38 | G531: 16 | H531: 14 | I531: 1 | J531: 0 | K531: =VLOOKUP(A531,'Team Data'!$A$1:$E$659,2,FALSE()) -> 1 | L531: =VLOOKUP(A531,'Team Data'!$A$1:$E$659,3,FALSE()) -> 2 | M531: =VLOOKUP(B531,'Team Data'!$A$1:$E$659,2,FALSE()) -> 16 | N531: =VLOOKUP(B531,'Team Data'!$A$1:$E$659,3,FALSE()) -> 17 | O531: =VLOOKUP(A531,'Team Data'!$A$1:$E$659,4,FALSE()) -> 44 | P531: =VLOOKUP(A531,'Team Data'!$A$1:$E$659,5,FALSE()) -> 53 | Q531: =VLOOKUP(B531,'Team Data'!$A$1:$E$659,4,FALSE()) -> 503 | R531: =VLOOKUP(B531,'Team Data'!$A$1:$E$659,5,FALSE()) -> 522 | S531: =IF(I531=1,(MIN(30,(C531-D531)))*(M531/(M531+N531))*(Q531/(Q531+R531)),(MAX(-30,(C531-D531)))*(N531/(M531+N531))*(R531/(R531+Q531))) -> 3.3310273 | T531: =IF(J531=1,(MIN(30,(D531-C531)))*(K531/(K531+L531))*(O531/(O531+P531)),(MAX(-30,(D531-C531)))*(L531/(K531+L531))*(P531/(P531+O531))) -> -5.0996564 | U531: 43057
A532: South Carolina State | B532: UCLA | C532: 68 | D532: 96 | E532: 30 | F532: 51 | G532: 10 | H532: 12 | I532: 0 | J532: 1 | K532: =VLOOKUP(A532,'Team Data'!$A$1:$E$659,2,FALSE()) -> 10 | L532: =VLOOKUP(A532,'Team Data'!$A$1:$E$659,3,FALSE()) -> 22 | M532: =VLOOKUP(B532,'Team Data'!$A$1:$E$659,2,FALSE()) -> 21 | N532: =VLOOKUP(B532,'Team Data'!$A$1:$E$659,3,FALSE()) -> 12 | O532: =VLOOKUP(A532,'Team Data'!$A$1:$E$659,4,FALSE()) -> 457 | P532: =VLOOKUP(A532,'Team Data'!$A$1:$E$659,5,FALSE()) -> 529 | Q532: =VLOOKUP(B532,'Team Data'!$A$1:$E$659,4,FALSE()) -> 636 | R532: =VLOOKUP(B532,'Team Data'!$A$1:$E$659,5,FALSE()) -> 474 | S532: =IF(I532=1,(MIN(30,(C532-D532)))*(M532/(M532+N532))*(Q532/(Q532+R532)),(MAX(-30,(C532-D532)))*(N532/(M532+N532))*(R532/(R532+Q532))) -> -4.3479115 | T532: =IF(J532=1,(MIN(30,(D532-C532)))*(K532/(K532+L532))*(O532/(O532+P532)),(MAX(-30,(D532-C532)))*(L532/(K532+L532))*(P532/(P532+O532))) -> 4.0555274 | U532: 43057
A533: Clemson | B533: Hofstra | C533: 78 | D533: 59 | E533: 35 | F533: 36 | G533: 6 | H533: 13 | I533: 1 | J533: 0 | K533: =VLOOKUP(A533,'Team Data'!$A$1:$E$659,2,FALSE()) -> 24 | L533: =VLOOKUP(A533,'Team Data'!$A$1:$E$659,3,FALSE()) -> 9 | M533: =VLOOKUP(B533,'Team Data'!$A$1:$E$659,2,FALSE()) -> 19 | N533: =VLOOKUP(B533,'Team Data'!$A$1:$E$659,3,FALSE()) -> 12 | O533: =VLOOKUP(A533,'Team Data'!$A$1:$E$659,4,FALSE()) -> 691 | P533: =VLOOKUP(A533,'Team Data'!$A$1:$E$659,5,FALSE()) -> 426 | Q533: =VLOOKUP(B533,'Team Data'!$A$1:$E$659,4,FALSE()) -> 498 | R533: =VLOOKUP(B533,'Team Data'!$A$1:$E$659,5,FALSE()) -> 473 | S533: =IF(I533=1,(MIN(30,(C533-D533)))*(M533/(M533+N533))*(Q533/(Q533+R533)),(MAX(-30,(C533-D533)))*(N533/(M533+N533))*(R533/(R533+Q533))) -> 5.9724926 | T533: =IF(J533=1,(MIN(30,(D533-C533)))*(K533/(K533+L533))*(O533/(O533+P533)),(MAX(-30,(D533-C533)))*(L533/(K533+L533))*(P533/(P533+O533))) -> -1.976235 | U533: 43057
A534: Sacramento State | B534: San Francisco | C534: 56 | D534: 69 | E534: 34 | F534: 43 | G534: 14 | H534: 5 | I534: 0 | J534: 1 | K534: =VLOOKUP(A534,'Team Data'!$A$1:$E$659,2,FALSE()) -> 7 | L534: =VLOOKUP(A534,'Team Data'!$A$1:$E$659,3,FALSE()) -> 25 | M534: =VLOOKUP(B534,'Team Data'!$A$1:$E$659,2,FALSE()) -> 22 | N534: =VLOOKUP(B534,'Team Data'!$A$1:$E$659,3,FALSE()) -> 17 | O534: =VLOOKUP(A534,'Team Data'!$A$1:$E$659,4,FALSE()) -> 549 | P534: =VLOOKUP(A534,'Team Data'!$A$1:$E$659,5,FALSE()) -> 437 | Q534: =VLOOKUP(B534,'Team Data'!$A$1:$E$659,4,FALSE()) -> 712 | R534: =VLOOKUP(B534,'Team Data'!$A$1:$E$659,5,FALSE()) -> 575 | S534: =IF(I534=1,(MIN(30,(C534-D534)))*(M534/(M534+N534))*(Q534/(Q534+R534)),(MAX(-30,(C534-D534)))*(N534/(M534+N534))*(R534/(R534+Q534))) -> -2.5317275 | T534: =IF(J534=1,(MIN(30,(D534-C534)))*(K534/(K534+L534))*(O534/(O534+P534)),(MAX(-30,(D534-C534)))*(L534/(K534+L534))*(P534/(P534+O534))) -> 1.5833862 | U534: 43057
A535: Eastern Washington | B535: UNLV | C535: 76 | D535: 91 | E535: 33 | F535: 44 | G535: 8 | H535: 15 | I535: 0 | J535: 1 | K535: =VLOOKUP(A535,'Team Data'!$A$1:$E$659,2,FALSE()) -> 20 | L535: =VLOOKUP(A535,'Team Data'!$A$1:$E$659,3,FALSE()) -> 15 | M535: =VLOOKUP(B535,'Team Data'!$A$1:$E$659,2,FALSE()) -> 20 | N535: =VLOOKUP(B535,'Team Data'!$A$1:$E$659,3,FALSE()) -> 13 | O535: =VLOOKUP(A535,'Team Data'!$A$1:$E$659,4,FALSE()) -> 577 | P535: =VLOOKUP(A535,'Team Data'!$A$1:$E$659,5,FALSE()) -> 520 | Q535: =VLOOKUP(B535,'Team Data'!$A$1:$E$659,4,FALSE()) -> 561 | R535: =VLOOKUP(B535,'Team Data'!$A$1:$E$659,5,FALSE()) -> 525 | S535: =IF(I535=1,(MIN(30,(C535-D535)))*(M535/(M535+N535))*(Q535/(Q535+R535)),(MAX(-30,(C535-D535)))*(N535/(M535+N535))*(R535/(R535+Q535))) -> -2.8566047 | T535: =IF(J535=1,(MIN(30,(D535-C535)))*(K535/(K535+L535))*(O535/(O535+P535)),(MAX(-30,(D535-C535)))*(L535/(K535+L535))*(P535/(P535+O535))) -> 4.5083995 | U535: 43057
A536: Northern Colorado | B536: Pepperdine | C536: 84 | D536: 82 | E536: 38 | F536: 44 | G536: 10 | H536: 7 | I536: 1 | J536: 0 | K536: =VLOOKUP(A536,'Team Data'!$A$1:$E$659,2,FALSE()) -> 26 | L536: =VLOOKUP(A536,'Team Data'!$A$1:$E$659,3,FALSE()) -> 12 | M536: =VLOOKUP(B536,'Team Data'!$A$1:$E$659,2,FALSE()) -> 6 | N536: =VLOOKUP(B536,'Team Data'!$A$1:$E$659,3,FALSE()) -> 26 | O536: =VLOOKUP(A536,'Team Data'!$A$1:$E$659,4,FALSE()) -> 600 | P536: =VLOOKUP(A536,'Team Data'!$A$1:$E$659,5,FALSE()) -> 551 | Q536: =VLOOKUP(B536,'Team Data'!$A$1:$E$659,4,FALSE()) -> 578 | R536: =VLOOKUP(B536,'Team Data'!$A$1:$E$659,5,FALSE()) -> 464 | S536: =IF(I536=1,(MIN(30,(C536-D536)))*(M536/(M536+N536))*(Q536/(Q536+R536)),(MAX(-30,(C536-D536)))*(N536/(M536+N536))*(R536/(R536+Q536))) -> 0.20801344 | T536: =IF(J536=1,(MIN(30,(D536-C536)))*(K536/(K536+L536))*(O536/(O536+P536)),(MAX(-30,(D536-C536)))*(L536/(K536+L536))*(P536/(P536+O536))) -> -0.30234579 | U536: 43057
... A583: Florida Gulf Coast | B583: Bowling Green | C583: 80 | D583: 83 | E583: 42 | F583: 46 | G583: 16 | H583: 14 | I583: 0 | J583: 1 | K583: =VLOOKUP(A583,'Team Data'!$A$1:$E$659,2,FALSE()) -> 23 | L583: =VLOOKUP(A583,'Team Data'!$A$1:$E$659,3,FALSE()) -> 12 | M583: =VLOOKUP(B583,'Team Data'!$A$1:$E$659,2,FALSE()) -> 16 | N583: =VLOOKUP(B583,'Team Data'!$A$1:$E$659,3,FALSE()) -> 16 | O583: =VLOOKUP(A583,'Team Data'!$A$1:$E$659,4,FALSE()) -> 500 | P583: =VLOOKUP(A583,'Team Data'!$A$1:$E$659,5,FALSE()) -> 533 | Q583: =VLOOKUP(B583,'Team Data'!$A$1:$E$659,4,FALSE()) -> 523 | R583: =VLOOKUP(B583,'Team Data'!$A$1:$E$659,5,FALSE()) -> 476 | S583: =IF(I583=1,(MIN(30,(C583-D583)))*(M583/(M583+N583))*(Q583/(Q583+R583)),(MAX(-30,(C583-D583)))*(N583/(M583+N583))*(R583/(R583+Q583))) -> -0.71471471 | T583: =IF(J583=1,(MIN(30,(D583-C583)))*(K583/(K583+L583))*(O583/(O583+P583)),(MAX(-30,(D583-C583)))*(L583/(K583+L583))*(P583/(P583+O583))) -> 0.95422487 | U583: 43057
A584: Hartford | B584: Long Island University | C584: 84 | D584: 86 | I584: 0 | J584: 1 | K584: =VLOOKUP(A584,'Team Data'!$A$1:$E$659,2,FALSE()) -> 19 | L584: =VLOOKUP(A584,'Team Data'!$A$1:$E$659,3,FALSE()) -> 14 | M584: =VLOOKUP(B584,'Team Data'!$A$1:$E$659,2,FALSE()) -> 18 | N584: =VLOOKUP(B584,'Team Data'!$A$1:$E$659,3,FALSE()) -> 17 | O584: =VLOOKUP(A584,'Team Data'!$A$1:$E$659,4,FALSE()) -> 501 | P584: =VLOOKUP(A584,'Team Data'!$A$1:$E$659,5,FALSE()) -> 542 | Q584: =VLOOKUP(B584,'Team Data'!$A$1:$E$659,4,FALSE()) -> 497 | R584: =VLOOKUP(B584,'Team Data'!$A$1:$E$659,5,FALSE()) -> 580 | S584: =IF(I584=1,(MIN(30,(C584-D584)))*(M584/(M584+N584))*(Q584/(Q584+R584)),(MAX(-30,(C584-D584)))*(N584/(M584+N584))*(R584/(R584+Q584))) -> -0.52314631 | T584: =IF(J584=1,(MIN(30,(D584-C584)))*(K584/(K584+L584))*(O584/(O584+P584)),(MAX(-30,(D584-C584)))*(L584/(K584+L584))*(P584/(P584+O584))) -> 0.55312473 | U584: 43057
A585: Mercer | B585: Drexel | C585: 78 | D585: 59 | E585: 38 | F585: 38 | G585: 5 | H585: 13 | I585: 1 | J585: 0 | K585: =VLOOKUP(A585,'Team Data'!$A$1:$E$659,2,FALSE()) -> 19 | L585: =VLOOKUP(A585,'Team Data'!$A$1:$E$659,3,FALSE()) -> 15 | M585: =VLOOKUP(B585,'Team Data'!$A$1:$E$659,2,FALSE()) -> 13 | N585: =VLOOKUP(B585,'Team Data'!$A$1:$E$659,3,FALSE()) -> 20 | O585: =VLOOKUP(A585,'Team Data'!$A$1:$E$659,4,FALSE()) -> 543 | P585: =VLOOKUP(A585,'Team Data'!$A$1:$E$659,5,FALSE()) -> 527 | Q585: =VLOOKUP(B585,'Team Data'!$A$1:$E$659,4,FALSE()) -> 534 | R585: =VLOOKUP(B585,'Team Data'!$A$1:$E$659,5,FALSE()) -> 500 | S585: =IF(I585=1,(MIN(30,(C585-D585)))*(M585/(M585+N585))*(Q585/(Q585+R585)),(MAX(-30,(C585-D585)))*(N585/(M585+N585))*(R585/(R585+Q585))) -> 3.8654827 | T585: =IF(J585=1,(MIN(30,(D585-C585)))*(K585/(K585+L585))*(O585/(O585+P585)),(MAX(-30,(D585-C585)))*(L585/(K585+L585))*(P585/(P585+O585))) -> -4.1285047 | U585: 43057
A586: North Carolina A&T | B586: Jacksonville | C586: 90 | D586: 82 | E586: 38 | F586: 33 | G586: 12 | H586: 10 | I586: 1 | J586: 0 | K586: =VLOOKUP(A586,'Team Data'!$A$1:$E$659,2,FALSE()) -> 20 | L586: =VLOOKUP(A586,'Team Data'!$A$1:$E$659,3,FALSE()) -> 15 | M586: =VLOOKUP(B586,'Team Data'!$A$1:$E$659,2,FALSE()) -> 15 | N586: =VLOOKUP(B586,'Team Data'!$A$1:$E$659,3,FALSE()) -> 18 | O586: =VLOOKUP(A586,'Team Data'!$A$1:$E$659,4,FALSE()) -> 455 | P586: =VLOOKUP(A586,'Team Data'!$A$1:$E$659,5,FALSE()) -> 629 | Q586: =VLOOKUP(B586,'Team Data'!$A$1:$E$659,4,FALSE()) -> 463 | R586: =VLOOKUP(B586,'Team Data'!$A$1:$E$659,5,FALSE()) -> 494 | S586: =IF(I586=1,(MIN(30,(C586-D586)))*(M586/(M586+N586))*(Q586/(Q586+R586)),(MAX(-30,(C586-D586)))*(N586/(M586+N586))*(R586/(R586+Q586))) -> 1.7592856 | T586: =IF(J586=1,(MIN(30,(D586-C586)))*(K586/(K586+L586))*(O586/(O586+P586)),(MAX(-30,(D586-C586)))*(L586/(K586+L586))*(P586/(P586+O586))) -> -1.989457 | U586: 43057
A587: Cal State Northridge | B587: George Mason | C587: 73 | D587: 78 | E587: 34 | F587: 45 | G587: 12 | H587: 15 | I587: 0 | J587: 1 | K587: =VLOOKUP(A587,'Team Data'!$A$1:$E$659,2,FALSE()) -> 6 | L587: =VLOOKUP(A587,'Team Data'!$A$1:$E$659,3,FALSE()) -> 24 | M587: =VLOOKUP(B587,'Team Data'!$A$1:$E$659,2,FALSE()) -> 16 | N587: =VLOOKUP(B587,'Team Data'!$A$1:$E$659,3,FALSE()) -> 17 | O587: =VLOOKUP(A587,'Team Data'!$A$1:$E$659,4,FALSE()) -> 441 | P587: =VLOOKUP(A587,'Team Data'!$A$1:$E$659,5,FALSE()) -> 464 | Q587: =VLOOKUP(B587,'Team Data'!$A$1:$E$659,4,FALSE()) -> 539 | R587: =VLOOKUP(B587,'Team Data'!$A$1:$E$659,5,FALSE()) -> 535 | S587: =IF(I587=1,(MIN(30,(C587-D587)))*(M587/(M587+N587))*(Q587/(Q587+R587)),(MAX(-30,(C587-D587)))*(N587/(M587+N587))*(R587/(R587+Q587))) -> -1.2830822 | T587: =IF(J587=1,(MIN(30,(D587-C587)))*(K587/(K587+L587))*(O587/(O587+P587)),(MAX(-30,(D587-C587)))*(L587/(K587+L587))*(P587/(P587+O587))) -> 0.48729282 | U587: 43057
A588: Florida International | B588: Milwaukee | C588: 51 | D588: 66 | E588: 29 | F588: 37 | G588: 9 | H588: 13 | I588: 0 | J588: 1 | K588: =VLOOKUP(A588,'Team Data'!$A$1:$E$659,2,FALSE()) -> 14 | L588: =VLOOKUP(A588,'Team Data'!$A$1:$E$659,3,FALSE()) -> 18 | M588: =VLOOKUP(B588,'Team Data'!$A$1:$E$659,2,FALSE()) -> 16 | N588: =VLOOKUP(B588,'Team Data'!$A$1:$E$659,3,FALSE()) -> 17 | O588: =VLOOKUP(A588,'Team Data'!$A$1:$E$659,4,FALSE()) -> 467 | P588: =VLOOKUP(A588,'Team Data'!$A$1:$E$659,5,FALSE()) -> 496 | Q588: =VLOOKUP(B588,'Team Data'!$A$1:$E$659,4,FALSE()) -> 503 | R588: =VLOOKUP(B588,'Team Data'!$A$1:$E$659,5,FALSE()) -> 522 | S588: =IF(I588=1,(MIN(30,(C588-D588)))*(M588/(M588+N588))*(Q588/(Q588+R588)),(MAX(-30,(C588-D588)))*(N588/(M588+N588))*(R588/(R588+Q588))) -> -3.935255 | T588: =IF(J588=1,(MIN(30,(D588-C588)))*(K588/(K588+L588))*(O588/(O588+P588)),(MAX(-30,(D588-C588)))*(L588/(K588+L588))*(P588/(P588+O588))) -> 3.1824377 | U588: 43057
A589: Fairfield | B589: Purdue | C589: 64 | D589: 106 | E589: 34 | F589: 42 | G589: 22 | H589: 9 | I589: 0 | J589: 1 | K589: =VLOOKUP(A589,'Team Data'!$A$1:$E$659,2,FALSE()) -> 17 | L589: =VLOOKUP(A589,'Team Data'!$A$1:$E$659,3,FALSE()) -> 16 | M589: =VLOOKUP(B589,'Team Data'!$A$1:$E$659,2,FALSE()) -> 30 | N589: =VLOOKUP(B589,'Team Data'!$A$1:$E$659,3,FALSE()) -> 7 | O589: =VLOOKUP(A589,'Team Data'!$A$1:$E$659,4,FALSE()) -> 536 | P589: =VLOOKUP(A589,'Team Data'!$A$1:$E$659,5,FALSE()) -> 539 | Q589: =VLOOKUP(B589,'Team Data'!$A$1:$E$659,4,FALSE()) -> 726 | R589: =VLOOKUP(B589,'Team Data'!$A$1:$E$659,5,FALSE()) -> 521 | S589: =IF(I589=1,(MIN(30,(C589-D589)))*(M589/(M589+N589))*(Q589/(Q589+R589)),(MAX(-30,(C589-D589)))*(N589/(M589+N589))*(R589/(R589+Q589))) -> -2.3713128 | T589: =IF(J589=1,(MIN(30,(D589-C589)))*(K589/(K589+L589))*(O589/(O589+P589)),(MAX(-30,(D589-C589)))*(L589/(K589+L589))*(P589/(P589+O589))) -> 7.7057082 | U589: 43058
A590: Charleston | B590: Charlotte | C590: 81 | D590: 72 | E590: 34 | F590: 36 | G590: 16 | H590: 17 | I590: 1 | J590: 0 | K590: =VLOOKUP(A590,'Team Data'!$A$1:$E$659,2,FALSE()) -> 26 | L590: =VLOOKUP(A590,'Team Data'!$A$1:$E$659,3,FALSE()) -> 8 | M590: =VLOOKUP(B590,'Team Data'!$A$1:$E$659,2,FALSE()) -> 6 | N590: =VLOOKUP(B590,'Team Data'!$A$1:$E$659,3,FALSE()) -> 23 | O590: =VLOOKUP(A590,'Team Data'!$A$1:$E$659,4,FALSE()) -> 508 | P590: =VLOOKUP(A590,'Team Data'!$A$1:$E$659,5,FALSE()) -> 524 | Q590: =VLOOKUP(B590,'Team Data'!$A$1:$E$659,4,FALSE()) -> 485 | R590: =VLOOKUP(B590,'Team Data'!$A$1:$E$659,5,FALSE()) -> 443 | S590: =IF(I590=1,(MIN(30,(C590-D590)))*(M590/(M590+N590))*(Q590/(Q590+R590)),(MAX(-30,(C590-D590)))*(N590/(M590+N590))*(R590/(R590+Q590))) -> 0.97317182 | T590: =IF(J590=1,(MIN(30,(D590-C590)))*(K590/(K590+L590))*(O590/(O590+P590)),(MAX(-30,(D590-C590)))*(L590/(K590+L590))*(P590/(P590+O590))) -> -1.0752394 | U590: 43058
A591: Oakland | B591: Toledo | C591: 74 | D591: 87 | E591: 41 | F591: 45 | G591: 10 | H591: 8 | I591: 0 | J591: 1 | K591: =VLOOKUP(A591,'Team Data'!$A$1:$E$659,2,FALSE()) -> 19 | L591: =VLOOKUP(A591,'Team Data'!$A$1:$E$659,3,FALSE()) -> 14 | M591: =VLOOKUP(B591,'Team Data'!$A$1:$E$659,2,FALSE()) -> 23 | N591: =VLOOKUP(B591,'Team Data'!$A$1:$E$659,3,FALSE()) -> 11 | O591: =VLOOKUP(A591,'Team Data'!$A$1:$E$659,4,FALSE()) -> 541 | P591: =VLOOKUP(A591,'Team Data'!$A$1:$E$659,5,FALSE()) -> 562 | Q591: =VLOOKUP(B591,'Team Data'!$A$1:$E$659,4,FALSE()) -> 603 | R591: =VLOOKUP(B591,'Team Data'!$A$1:$E$659,5,FALSE()) -> 503 | S591: =IF(I591=1,(MIN(30,(C591-D591)))*(M591/(M591+N591))*(Q591/(Q591+R591)),(MAX(-30,(C591-D591)))*(N591/(M591+N591))*(R591/(R591+Q591))) -> -1.9128018 | T591: =IF(J591=1,(MIN(30,(D591-C591)))*(K591/(K591+L591))*(O591/(O591+P591)),(MAX(-30,(D591-C591)))*(L591/(K591+L591))*(P591/(P591+O591))) -> 3.6711723 | U591: 43058
A592: UT Martin | B592: Akron | C592: 59 | D592: 76 | E592: 31 | F592: 32 | G592: 13 | H592: 14 | I592: 0 | J592: 1 | K592: =VLOOKUP(A592,'Team Data'!$A$1:$E$659,2,FALSE()) -> 10 | L592: =VLOOKUP(A592,'Team Data'!$A$1:$E$659,3,FALSE()) -> 21 | M592: =VLOOKUP(B592,'Team Data'!$A$1:$E$659,2,FALSE()) -> 14 | N592: =VLOOKUP(B592,'Team Data'!$A$1:$E$659,3,FALSE()) -> 18 | O592: =VLOOKUP(A592,'Team Data'!$A$1:$E$659,4,FALSE()) -> 453 | P592: =VLOOKUP(A592,'Team Data'!$A$1:$E$659,5,FALSE()) -> 488 | Q592: =VLOOKUP(B592,'Team Data'!$A$1:$E$659,4,FALSE()) -> 542 | R592: =VLOOKUP(B592,'Team Data'!$A$1:$E$659,5,FALSE()) -> 488 | S592: =IF(I592=1,(MIN(30,(C592-D592)))*(M592/(M592+N592))*(Q592/(Q592+R592)),(MAX(-30,(C592-D592)))*(N592/(M592+N592))*(R592/(R592+Q592))) -> -4.5305825 | T592: =IF(J592=1,(MIN(30,(D592-C592)))*(K592/(K592+L592))*(O592/(O592+P592)),(MAX(-30,(D592-C592)))*(L592/(K592+L592))*(P592/(P592+O592))) -> 2.6399506 | U592: 43058
A593: Princeton | B593: Saint Joseph's | C593: 58 | D593: 71 | E593: 25 | F593: 30 | G593: 9 | H593: 4 | I593: 0 | J593: 1 | K593: =VLOOKUP(A593,'Team Data'!$A$1:$E$659,2,FALSE()) -> 13 | L593: =VLOOKUP(A593,'Team Data'!$A$1:$E$659,3,FALSE()) -> 16 | M593: =VLOOKUP(B593,'Team Data'!$A$1:$E$659,2,FALSE()) -> 16 | N593: =VLOOKUP(B593,'Team Data'!$A$1:$E$659,3,FALSE()) -> 16 | O593: =VLOOKUP(A593,'Team Data'!$A$1:$E$659,4,FALSE()) -> 429 | P593: =VLOOKUP(A593,'Team Data'!$A$1:$E$659,5,FALSE()) -> 434 | Q593: =VLOOKUP(B593,'Team Data'!$A$1:$E$659,4,FALSE()) -> 549 | R593: =VLOOKUP(B593,'Team Data'!$A$1:$E$659,5,FALSE()) -> 500 | S593: =IF(I593=1,(MIN(30,(C593-D593)))*(M593/(M593+N593))*(Q593/(Q593+R593)),(MAX(-30,(C593-D593)))*(N593/(M593+N593))*(R593/(R593+Q593))) -> -3.0981888 | T593: =IF(J593=1,(MIN(30,(D593-C593)))*(K593/(K593+L593))*(O593/(O593+P593)),(MAX(-30,(D593-C593)))*(L593/(K593+L593))*(P593/(P593+O593))) -> 2.8969113 | U593: 43058
A594: Texas Southern | B594: Syracuse | C594: 67 | D594: 80 | E594: 28 | F594: 40 | G594: 10 | H594: 10 | I594: 0 | J594: 1 | K594: =VLOOKUP(A594,'Team Data'!$A$1:$E$659,2,FALSE()) -> 16 | L594: =VLOOKUP(A594,'Team Data'!$A$1:$E$659,3,FALSE()) -> 19 | M594: =VLOOKUP(B594,'Team Data'!$A$1:$E$659,2,FALSE()) -> 23 | N594: =VLOOKUP(B594,'Team Data'!$A$1:$E$659,3,FALSE()) -> 14 | O594: =VLOOKUP(A594,'Team Data'!$A$1:$E$659,4,FALSE()) -> 549 | P594: =VLOOKUP(A594,'Team Data'!$A$1:$E$659,5,FALSE()) -> 611 | Q594: =VLOOKUP(B594,'Team Data'!$A$1:$E$659,4,FALSE()) -> 752 | R594: =VLOOKUP(B594,'Team Data'!$A$1:$E$659,5,FALSE()) -> 485 | S594: =IF(I594=1,(MIN(30,(C594-D594)))*(M594/(M594+N594))*(Q594/(Q594+R594)),(MAX(-30,(C594-D594)))*(N594/(M594+N594))*(R594/(R594+Q594))) -> -1.928598 | T594: =IF(J594=1,(MIN(30,(D594-C594)))*(K594/(K594+L594))*(O594/(O594+P594)),(MAX(-30,(D594-C594)))*(L594/(K594+L594))*(P594/(P594+O594))) -> 2.8126108 | U594: 43058
A595: Murray State | B595: Wright State | C595: 80 | D595: 61 | E595: 35 | F595: 29 | G595: 15 | H595: 16 | I595: 1 | J595: 0 | K595: =VLOOKUP(A595,'Team Data'!$A$1:$E$659,2,FALSE()) -> 26 | L595: =VLOOKUP(A595,'Team Data'!$A$1:$E$659,3,FALSE()) -> 6 | M595: =VLOOKUP(B595,'Team Data'!$A$1:$E$659,2,FALSE()) -> 25 | N595: =VLOOKUP(B595,'Team Data'!$A$1:$E$659,3,FALSE()) -> 10 | O595: =VLOOKUP(A595,'Team Data'!$A$1:$E$659,4,FALSE()) -> 495 | P595: =VLOOKUP(A595,'Team Data'!$A$1:$E$659,5,FALSE()) -> 480 | Q595: =VLOOKUP(B595,'Team Data'!$A$1:$E$659,4,FALSE()) -> 543 | R595: =VLOOKUP(B595,'Team Data'!$A$1:$E$659,5,FALSE()) -> 561 | S595: =IF(I595=1,(MIN(30,(C595-D595)))*(M595/(M595+N595))*(Q595/(Q595+R595)),(MAX(-30,(C595-D595)))*(N595/(M595+N595))*(R595/(R595+Q595))) -> 6.6750776 | T595: =IF(J595=1,(MIN(30,(D595-C595)))*(K595/(K595+L595))*(O595/(O595+P595)),(MAX(-30,(D595-C595)))*(L595/(K595+L595))*(P595/(P595+O595))) -> -1.7538462 | U595: 43058
...

Sheet Team Data
A1: Team | B1: W | C1: L | D1: Opp W | E1: Opp L | F1: O2 W | G1: O2 L | H1: Pnts | I1: Rebs | J1: O Rebs | K1: TO's | L1: O TO's | M1: Away Win | N1: Away Loss | O1: Reb Diff | P1: RDPG | Q1: TO Diff | R1: TODPG | S1: Conference | T1: MRI Score | U1: SOS | V1: SOS Rank
A2: Abilene Christian | B2: =SUMIF(Games!$A$2:$A$5969,$A2,Games!$I$2:$I$5969)+SUMIF(Games!$B$2:$B$5969,$A2,Games!$J$2:$J$5969) -> 16 | C2: =COUNTIF(Games!$A:$A,$A2)+COUNTIF(Games!$B:$B,$A2)-B2 -> 16 | D2: =SUMIF(Games!$A$2:$A$5969,$A2,Games!$M$2:$M$5969)+SUMIF(Games!$B$2:$B$5969,$A2,Games!$K$2:$K$5969) -> 459 | E2: =SUMIF(Games!$A$2:$A$5969,$A2,Games!$N$2:$N$5969)+SUMIF(Games!$B$2:$B$5969,$A2,Games!$L$2:$L$5969) -> 461 | F2: =SUMIF(Games!$A$2:$A$5969,$A2,Games!$Q$2:$Q$5969)+SUMIF(Games!$B$2:$B$5969,$A2,Games!$O$2:$O$5969) -> 13912 | G2: =SUMIF(Games!$A$2:$A$5969,$A2,Games!$R$2:$R$5969)+SUMIF(Games!$B$2:$B$5969,$A2,Games!$P$2:$P$5969) -> 13604 | H2: =SUMIF(Games!$A$2:$A$5969,$A2,Games!$S$2:$S$5969)+SUMIF(Games!$B$2:$B$5969,$A2,Games!$T$2:$T$5969) -> -15.370408 | I2: =SUMIF(Games!$A$2:$A$5969,$A2,Games!$E$2:$E$5969)+SUMIF(Games!$B$2:$B$5969,$A2,Games!$F$2:$F$5969) -> 1097 | J2: =SUMIF(Games!$A$2:$A$5969,$A2,Games!$F$2:$F$5969)+SUMIF(Games!$B$2:$B$5969,$A2,Games!$E$2:$E$5969) -> 1111 | K2: =SUMIF(Games!$A$2:$A$5969,$A2,Games!$G$2:$G$5969)+SUMIF(Games!$B$2:$B$5969,$A2,Games!$H$2:$H$5969) -> 461 | L2: =SUMIF(Games!$A$2:$A$5969,$A2,Games!$H$2:$H$5969)+SUMIF(Games!$B$2:$B$5969,$A2,Games!$G$2:$G$5969) -> 513 | M2: =SUMIF(Games!$A:$A,$A2,Games!I:I) -> 7 | N2: =COUNTIF(Games!$A:$A,$A2)-M2 -> 9 | O2: =I2-J2 -> -14 | P2: =IFERROR(O2/Y2,0) -> -0.4375 | Q2: =L2-K2 -> 52 | R2: =IFERROR(Q2/Y2,0) -> 1.625 | S2: Southland | T2: =IFERROR((B2/(B2+C2))*25,0)+IFERROR((D2/(D2+E2))*25,0)+IFERROR((F2/(F2+G2))*10,0)+H2+((P2-RDAVG)/RebSD)*10+((R2-TODAVG)/TOSD)*6 -> 16.790575 | U2: =W2*X2 -> 0.25233693 | V2: =RANK(U2,U$2:U$352) -> 257 | W2: =IFERROR((D2-C2)/(D2+E2-(B2+C2)),0) -> 0.49887387 | X2: =IFERROR((F2-((B2+C2)*B2))/((F2+G2)-(B2+C2)^2),0) -> 0.50581308 | Y2: =COUNTIFS(Games!$A$2:$A$5969,$A2,Games!$E$2:$E$5969,"<>")+COUNTIFS(Games!$B$2:$B$5969,$A2,Games!$F$2:$F$5969,"<>") -> 32
A3: Air Force | B3: =SUMIF(Games!$A$2:$A$5969,$A3,Games!$I$2:$I$5969)+SUMIF(Games!$B$2:$B$5969,$A3,Games!$J$2:$J$5969) -> 12 | C3: =COUNTIF(Games!$A:$A,$A3)+COUNTIF(Games!$B:$B,$A3)-B3 -> 19 | D3: =SUMIF(Games!$A$2:$A$5969,$A3,Games!$M$2:$M$5969)+SUMIF(Games!$B$2:$B$5969,$A3,Games!$K$2:$K$5969) -> 486 | E3: =SUMIF(Games!$A$2:$A$5969,$A3,Games!$N$2:$N$5969)+SUMIF(Games!$B$2:$B$5969,$A3,Games!$L$2:$L$5969) -> 454 | F3: =SUMIF(Games!$A$2:$A$5969,$A3,Games!$Q$2:$Q$5969)+SUMIF(Games!$B$2:$B$5969,$A3,Games!$O$2:$O$5969) -> 15764 | G3: =SUMIF(Games!$A$2:$A$5969,$A3,Games!$R$2:$R$5969)+SUMIF(Games!$B$2:$B$5969,$A3,Games!$P$2:$P$5969) -> 14061 | H3: =SUMIF(Games!$A$2:$A$5969,$A3,Games!$S$2:$S$5969)+SUMIF(Games!$B$2:$B$5969,$A3,Games!$T$2:$T$5969) -> -36.813035 | I3: =SUMIF(Games!$A$2:$A$5969,$A3,Games!$E$2:$E$5969)+SUMIF(Games!$B$2:$B$5969,$A3,Games!$F$2:$F$5969) -> 1014 | J3: =SUMIF(Games!$A$2:$A$5969,$A3,Games!$F$2:$F$5969)+SUMIF(Games!$B$2:$B$5969,$A3,Games!$E$2:$E$5969) -> 1069 | K3: =SUMIF(Games!$A$2:$A$5969,$A3,Games!$G$2:$G$5969)+SUMIF(Games!$B$2:$B$5969,$A3,Games!$H$2:$H$5969) -> 391 | L3: =SUMIF(Games!$A$2:$A$5969,$A3,Games!$H$2:$H$5969)+SUMIF(Games!$B$2:$B$5969,$A3,Games!$G$2:$G$5969) -> 436 | M3: =SUMIF(Games!$A:$A,$A3,Games!I:I) -> 3 | N3: =COUNTIF(Games!$A:$A,$A3)-M3 -> 12 | O3: =I3-J3 -> -55 | P3: =IFERROR(O3/Y3,0) -> -1.7741935 | Q3: =L3-K3 -> 45 | R3: =IFERROR(Q3/Y3,0) -> 1.4516129 | S3: Mountain West | T3: =IFERROR((B3/(B3+C3))*25,0)+IFERROR((D3/(D3+E3))*25,0)+IFERROR((F3/(F3+G3))*10,0)+H3+((P3-RDAVG)/RebSD)*10+((R3-TODAVG)/TOSD)*6 -> -11.066422 | U3: =W3*X3 -> 0.27396276 | V3: =RANK(U3,U$2:U$352) -> 170 | W3: =IFERROR((D3-C3)/(D3+E3-(B3+C3)),0) -> 0.51375138 | X3: =IFERROR((F3-((B3+C3)*B3))/((F3+G3)-(B3+C3)^2),0) -> 0.53325942 | Y3: =COUNTIFS(Games!$A$2:$A$5969,$A3,Games!$E$2:$E$5969,"<>")+COUNTIFS(Games!$B$2:$B$5969,$A3,Games!$F$2:$F$5969,"<>") -> 31
A4: Akron | B4: =SUMIF(Games!$A$2:$A$5969,$A4,Games!$I$2:$I$5969)+SUMIF(Games!$B$2:$B$5969,$A4,Games!$J$2:$J$5969) -> 14 | C4: =COUNTIF(Games!$A:$A,$A4)+COUNTIF(Games!$B:$B,$A4)-B4 -> 18 | D4: =SUMIF(Games!$A$2:$A$5969,$A4,Games!$M$2:$M$5969)+SUMIF(Games!$B$2:$B$5969,$A4,Games!$K$2:$K$5969) -> 542 | E4: =SUMIF(Games!$A$2:$A$5969,$A4,Games!$N$2:$N$5969)+SUMIF(Games!$B$2:$B$5969,$A4,Games!$L$2:$L$5969) -> 488 | F4: =SUMIF(Games!$A$2:$A$5969,$A4,Games!$Q$2:$Q$5969)+SUMIF(Games!$B$2:$B$5969,$A4,Games!$O$2:$O$5969) -> 17202 | G4: =SUMIF(Games!$A$2:$A$5969,$A4,Games!$R$2:$R$5969)+SUMIF(Games!$B$2:$B$5969,$A4,Games!$P$2:$P$5969) -> 15294 | H4: =SUMIF(Games!$A$2:$A$5969,$A4,Games!$S$2:$S$5969)+SUMIF(Games!$B$2:$B$5969,$A4,Games!$T$2:$T$5969) -> -26.802697 | I4: =SUMIF(Games!$A$2:$A$5969,$A4,Games!$E$2:$E$5969)+SUMIF(Games!$B$2:$B$5969,$A4,Games!$F$2:$F$5969) -> 1071 | J4: =SUMIF(Games!$A$2:$A$5969,$A4,Games!$F$2:$F$5969)+SUMIF(Games!$B$2:$B$5969,$A4,Games!$E$2:$E$5969) -> 1110 | K4: =SUMIF(Games!$A$2:$A$5969,$A4,Games!$G$2:$G$5969)+SUMIF(Games!$B$2:$B$5969,$A4,Games!$H$2:$H$5969) -> 440 | L4: =SUMIF(Games!$A$2:$A$5969,$A4,Games!$H$2:$H$5969)+SUMIF(Games!$B$2:$B$5969,$A4,Games!$G$2:$G$5969) -> 410 | M4: =SUMIF(Games!$A:$A,$A4,Games!I:I) -> 2 | N4: =COUNTIF(Games!$A:$A,$A4)-M4 -> 13 | O4: =I4-J4 -> -39 | P4: =IFERROR(O4/Y4,0) -> -1.21875 | Q4: =L4-K4 -> -30 | R4: =IFERROR(Q4/Y4,0) -> -0.9375 | S4: MAC | T4: =IFERROR((B4/(B4+C4))*25,0)+IFERROR((D4/(D4+E4))*25,0)+IFERROR((F4/(F4+G4))*10,0)+H4+((P4-RDAVG)/RebSD)*10+((R4-TODAVG)/TOSD)*6 -> -5.6445401 | U4: =W4*X4 -> 0.27950843 | V4: =RANK(U4,U$2:U$352) -> 146 | W4: =IFERROR((D4-C4)/(D4+E4-(B4+C4)),0) -> 0.5250501 | X4: =IFERROR((F4-((B4+C4)*B4))/((F4+G4)-(B4+C4)^2),0) -> 0.53234621 | Y4: =COUNTIFS(Games!$A$2:$A$5969,$A4,Games!$E$2:$E$5969,"<>")+COUNTIFS(Games!$B$2:$B$5969,$A4,Games!$F$2:$F$5969,"<>") -> 32
A5: Alabama | B5: =SUMIF(Games!$A$2:$A$5969,$A5,Games!$I$2:$I$5969)+SUMIF(Games!$B$2:$B$5969,$A5,Games!$J$2:$J$5969) -> 20 | C5: =COUNTIF(Games!$A:$A,$A5)+COUNTIF(Games!$B:$B,$A5)-B5 -> 16 | D5: =SUMIF(Games!$A$2:$A$5969,$A5,Games!$M$2:$M$5969)+SUMIF(Games!$B$2:$B$5969,$A5,Games!$K$2:$K$5969) -> 741 | E5: =SUMIF(Games!$A$2:$A$5969,$A5,Games!$N$2:$N$5969)+SUMIF(Games!$B$2:$B$5969,$A5,Games!$L$2:$L$5969) -> 460 | F5: =SUMIF(Games!$A$2:$A$5969,$A5,Games!$Q$2:$Q$5969)+SUMIF(Games!$B$2:$B$5969,$A5,Games!$O$2:$O$5969) -> 22627 | G5: =SUMIF(Games!$A$2:$A$5969,$A5,Games!$R$2:$R$5969)+SUMIF(Games!$B$2:$B$5969,$A5,Games!$P$2:$P$5969) -> 17100 | H5: =SUMIF(Games!$A$2:$A$5969,$A5,Games!$S$2:$S$5969)+SUMIF(Games!$B$2:$B$5969,$A5,Games!$T$2:$T$5969) -> 50.489099 | I5: =SUMIF(Games!$A$2:$A$5969,$A5,Games!$E$2:$E$5969)+SUMIF(Games!$B$2:$B$5969,$A5,Games!$F$2:$F$5969) -> 1293 | J5: =SUMIF(Games!$A$2:$A$5969,$A5,Games!$F$2:$F$5969)+SUMIF(Games!$B$2:$B$5969,$A5,Games!$E$2:$E$5969) -> 1284 | K5: =SUMIF(Games!$A$2:$A$5969,$A5,Games!$G$2:$G$5969)+SUMIF(Games!$B$2:$B$5969,$A5,Games!$H$2:$H$5969) -> 513 | L5: =SUMIF(Games!$A$2:$A$5969,$A5,Games!$H$2:$H$5969)+SUMIF(Games!$B$2:$B$5969,$A5,Games!$G$2:$G$5969) -> 472 | M5: =SUMIF(Games!$A:$A,$A5,Games!I:I) -> 6 | N5: =COUNTIF(Games!$A:$A,$A5)-M5 -> 10 | O5: =I5-J5 -> 9 | P5: =IFERROR(O5/Y5,0) -> 0.25 | Q5: =L5-K5 -> -41 | R5: =IFERROR(Q5/Y5,0) -> -1.1388889 | S5: SEC | T5: =IFERROR((B5/(B5+C5))*25,0)+IFERROR((D5/(D5+E5))*25,0)+IFERROR((F5/(F5+G5))*10,0)+H5+((P5-RDAVG)/RebSD)*10+((R5-TODAVG)/TOSD)*6 -> 80.71429 | U5: =W5*X5 -> 0.35474257 | V5: =RANK(U5,U$2:U$352) -> 5 | W5: =IFERROR((D5-C5)/(D5+E5-(B5+C5)),0) -> 0.6223176 | X5: =IFERROR((F5-((B5+C5)*B5))/((F5+G5)-(B5+C5)^2),0) -> 0.57003461 | Y5: =COUNTIFS(Games!$A$2:$A$5969,$A5,Games!$E$2:$E$5969,"<>")+COUNTIFS(Games!$B$2:$B$5969,$A5,Games!$F$2:$F$5969,"<>") -> 36
A6: Alabama A&M | B6: =SUMIF(Games!$A$2:$A$5969,$A6,Games!$I$2:$I$5969)+SUMIF(Games!$B$2:$B$5969,$A6,Games!$J$2:$J$5969) -> 3 | C6: =COUNTIF(Games!$A:$A,$A6)+COUNTIF(Games!$B:$B,$A6)-B6 -> 28 | D6: =SUMIF(Games!$A$2:$A$5969,$A6,Games!$M$2:$M$5969)+SUMIF(Games!$B$2:$B$5969,$A6,Games!$K$2:$K$5969) -> 453 | E6: =SUMIF(Games!$A$2:$A$5969,$A6,Games!$N$2:$N$5969)+SUMIF(Games!$B$2:$B$5969,$A6,Games!$L$2:$L$5969) -> 567 | F6: =SUMIF(Games!$A$2:$A$5969,$A6,Games!$Q$2:$Q$5969)+SUMIF(Games!$B$2:$B$5969,$A6,Games!$O$2:$O$5969) -> 15657 | G6: =SUMIF(Games!$A$2:$A$5969,$A6,Games!$R$2:$R$5969)+SUMIF(Games!$B$2:$B$5969,$A6,Games!$P$2:$P$5969) -> 16931 | H6: =SUMIF(Games!$A$2:$A$5969,$A6,Games!$S$2:$S$5969)+SUMIF(Games!$B$2:$B$5969,$A6,Games!$T$2:$T$5969) -> -118.73719 | I6: =SUMIF(Games!$A$2:$A$5969,$A6,Games!$E$2:$E$5969)+SUMIF(Games!$B$2:$B$5969,$A6,Games!$F$2:$F$5969) -> 1046 | J6: =SUMIF(Games!$A$2:$A$5969,$A6,Games!$F$2:$F$5969)+SUMIF(Games!$B$2:$B$5969,$A6,Games!$E$2:$E$5969) -> 1126 | K6: =SUMIF(Games!$A$2:$A$5969,$A6,Games!$G$2:$G$5969)+SUMIF(Games!$B$2:$B$5969,$A6,Games!$H$2:$H$5969) -> 512 | L6: =SUMIF(Games!$A$2:$A$5969,$A6,Games!$H$2:$H$5969)+SUMIF(Games!$B$2:$B$5969,$A6,Games!$G$2:$G$5969) -> 353 | M6: =SUMIF(Games!$A:$A,$A6,Games!I:I) -> 1 | N6: =COUNTIF(Games!$A:$A,$A6)-M6 -> 19 | O6: =I6-J6 -> -80 | P6: =IFERROR(O6/Y6,0) -> -2.5806452 | Q6: =L6-K6 -> -159 | R6: =IFERROR(Q6/Y6,0) -> -5.1290323 | S6: SWAC | T6: =IFERROR((B6/(B6+C6))*25,0)+IFERROR((D6/(D6+E6))*25,0)+IFERROR((F6/(F6+G6))*10,0)+H6+((P6-RDAVG)/RebSD)*10+((R6-TODAVG)/TOSD)*6 -> -125.81915 | U6: =W6*X6 -> 0.21147346 | V6: =RANK(U6,U$2:U$352) -> 340 | W6: =IFERROR((D6-C6)/(D6+E6-(B6+C6)),0) -> 0.429727 | X6: =IFERROR((F6-((B6+C6)*B6))/((F6+G6)-(B6+C6)^2),0) -> 0.49211117 | Y6: =COUNTIFS(Games!$A$2:$A$5969,$A6,Games!$E$2:$E$5969,"<>")+COUNTIFS(Games!$B$2:$B$5969,$A6,Games!$F$2:$F$5969,"<>") -> 31
A7: Alabama State | B7: =SUMIF(Games!$A$2:$A$5969,$A7,Games!$I$2:$I$5969)+SUMIF(Games!$B$2:$B$5969,$A7,Games!$J$2:$J$5969) -> 8 | C7: =COUNTIF(Games!$A:$A,$A7)+COUNTIF(Games!$B:$B,$A7)-B7 -> 23 | D7: =SUMIF(Games!$A$2:$A$5969,$A7,Games!$M$2:$M$5969)+SUMIF(Games!$B$2:$B$5969,$A7,Games!$K$2:$K$5969) -> 473 | E7: =SUMIF(Games!$A$2:$A$5969,$A7,Games!$N$2:$N$5969)+SUMIF(Games!$B$2:$B$5969,$A7,Games!$L$2:$L$5969) -> 559 | F7: =SUMIF(Games!$A$2:$A$5969,$A7,Games!$Q$2:$Q$5969)+SUMIF(Games!$B$2:$B$5969,$A7,Games!$O$2:$O$5969) -> 15473 | G7: =SUMIF(Games!$A$2:$A$5969,$A7,Games!$R$2:$R$5969)+SUMIF(Games!$B$2:$B$5969,$A7,Games!$P$2:$P$5969) -> 17242 | H7: =SUMIF(Games!$A$2:$A$5969,$A7,Games!$S$2:$S$5969)+SUMIF(Games!$B$2:$B$5969,$A7,Games!$T$2:$T$5969) -> -71.665246 | I7: =SUMIF(Games!$A$2:$A$5969,$A7,Games!$E$2:$E$5969)+SUMIF(Games!$B$2:$B$5969,$A7,Games!$F$2:$F$5969) -> 1131 | J7: =SUMIF(Games!$A$2:$A$5969,$A7,Games!$F$2:$F$5969)+SUMIF(Games!$B$2:$B$5969,$A7,Games!$E$2:$E$5969) -> 1232 | K7: =SUMIF(Games!$A$2:$A$5969,$A7,Games!$G$2:$G$5969)+SUMIF(Games!$B$2:$B$5969,$A7,Games!$H$2:$H$5969) -> 437 | L7: =SUMIF(Games!$A$2:$A$5969,$A7,Games!$H$2:$H$5969)+SUMIF(Games!$B$2:$B$5969,$A7,Games!$G$2:$G$5969) -> 401 | M7: =SUMIF(Games!$A:$A,$A7,Games!I:I) -> 4 | N7: =COUNTIF(Games!$A:$A,$A7)-M7 -> 15 | O7: =I7-J7 -> -101 | P7: =IFERROR(O7/Y7,0) -> -3.2580645 | Q7: =L7-K7 -> -36 | R7: =IFERROR(Q7/Y7,0) -> -1.1612903 | S7: SWAC | T7: =IFERROR((B7/(B7+C7))*25,0)+IFERROR((D7/(D7+E7))*25,0)+IFERROR((F7/(F7+G7))*10,0)+H7+((P7-RDAVG)/RebSD)*10+((R7-TODAVG)/TOSD)*6 -> -63.644418 | U7: =W7*X7 -> 0.21554467 | V7: =RANK(U7,U$2:U$352) -> 336 | W7: =IFERROR((D7-C7)/(D7+E7-(B7+C7)),0) -> 0.44955045 | X7: =IFERROR((F7-((B7+C7)*B7))/((F7+G7)-(B7+C7)^2),0) -> 0.47946715 | Y7: =COUNTIFS(Games!$A$2:$A$5969,$A7,Games!$E$2:$E$5969,"<>")+COUNTIFS(Games!$B$2:$B$5969,$A7,Games!$F$2:$F$5969,"<>") -> 31
A8: Alcorn State | B8: =SUMIF(Games!$A$2:$A$5969,$A8,Games!$I$2:$I$5969)+SUMIF(Games!$B$2:$B$5969,$A8,Games!$J$2:$J$5969) -> 11 | C8: =COUNTIF(Games!$A:$A,$A8)+COUNTIF(Games!$B:$B,$A8)-B8 -> 21 | D8: =SUMIF(Games!$A$2:$A$5969,$A8,Games!$M$2:$M$5969)+SUMIF(Games!$B$2:$B$5969,$A8,Games!$K$2:$K$5969) -> 370 | E8: =SUMIF(Games!$A$2:$A$5969,$A8,Games!$N$2:$N$5969)+SUMIF(Games!$B$2:$B$5969,$A8,Games!$L$2:$L$5969) -> 552 | F8: =SUMIF(Games!$A$2:$A$5969,$A8,Games!$Q$2:$Q$5969)+SUMIF(Games!$B$2:$B$5969,$A8,Games!$O$2:$O$5969) -> 14302 | G8: =SUMIF(Games!$A$2:$A$5969,$A8,Games!$R$2:$R$5969)+SUMIF(Games!$B$2:$B$5969,$A8,Games!$P$2:$P$5969) -> 15487 | H8: =SUMIF(Games!$A$2:$A$5969,$A8,Games!$S$2:$S$5969)+SUMIF(Games!$B$2:$B$5969,$A8,Games!$T$2:$T$5969) -> -76.746725 | I8: =SUMIF(Games!$A$2:$A$5969,$A8,Games!$E$2:$E$5969)+SUMIF(Games!$B$2:$B$5969,$A8,Games!$F$2:$F$5969) -> 1104 | J8: =SUMIF(Games!$A$2:$A$5969,$A8,Games!$F$2:$F$5969)+SUMIF(Games!$B$2:$B$5969,$A8,Games!$E$2:$E$5969) -> 1179 | K8: =SUMIF(Games!$A$2:$A$5969,$A8,Games!$G$2:$G$5969)+SUMIF(Games!$B$2:$B$5969,$A8,Games!$H$2:$H$5969) -> 460 | L8: =SUMIF(Games!$A$2:$A$5969,$A8,Games!$H$2:$H$5969)+SUMIF(Games!$B$2:$B$5969,$A8,Games!$G$2:$G$5969) -> 419 | M8: =SUMIF(Games!$A:$A,$A8,Games!I:I) -> 2 | N8: =COUNTIF(Games!$A:$A,$A8)-M8 -> 16 | O8: =I8-J8 -> -75 | P8: =IFERROR(O8/Y8,0) -> -2.34375 | Q8: =L8-K8 -> -41 | R8: =IFERROR(Q8/Y8,0) -> -1.28125 | S8: SWAC | T8: =IFERROR((B8/(B8+C8))*25,0)+IFERROR((D8/(D8+E8))*25,0)+IFERROR((F8/(F8+G8))*10,0)+H8+((P8-RDAVG)/RebSD)*10+((R8-TODAVG)/TOSD)*6 -> -65.776702 | U8: =W8*X8 -> 0.19017142 | V8: =RANK(U8,U$2:U$352) -> 350 | W8: =IFERROR((D8-C8)/(D8+E8-(B8+C8)),0) -> 0.39213483 | X8: =IFERROR((F8-((B8+C8)*B8))/((F8+G8)-(B8+C8)^2),0) -> 0.48496437 | Y8: =COUNTIFS(Games!$A$2:$A$5969,$A8,Games!$E$2:$E$5969,"<>")+COUNTIFS(Games!$B$2:$B$5969,$A8,Games!$F$2:$F$5969,"<>") -> 32
A9: American University | B9: =SUMIF(Games!$A$2:$A$5969,$A9,Games!$I$2:$I$5969)+SUMIF(Games!$B$2:$B$5969,$A9,Games!$J$2:$J$5969) -> 6 | C9: =COUNTIF(Games!$A:$A,$A9)+COUNTIF(Games!$B:$B,$A9)-B9 -> 24 | D9: =SUMIF(Games!$A$2:$A$5969,$A9,Games!$M$2:$M$5969)+SUMIF(Games!$B$2:$B$5969,$A9,Games!$K$2:$K$5969) -> 466 | E9: =SUMIF(Games!$A$2:$A$5969,$A9,Games!$N$2:$N$5969)+SUMIF(Games!$B$2:$B$5969,$A9,Games!$L$2:$L$5969) -> 488 | F9: =SUMIF(Games!$A$2:$A$5969,$A9,Games!$Q$2:$Q$5969)+SUMIF(Games!$B$2:$B$5969,$A9,Games!$O$2:$O$5969) -> 14321 | G9: =SUMIF(Games!$A$2:$A$5969,$A9,Games!$R$2:$R$5969)+SUMIF(Games!$B$2:$B$5969,$A9,Games!$P$2:$P$5969) -> 15253 | H9: =SUMIF(Games!$A$2:$A$5969,$A9,Games!$S$2:$S$5969)+SUMIF(Games!$B$2:$B$5969,$A9,Games!$T$2:$T$5969) -> -49.762331 | I9: =SUMIF(Games!$A$2:$A$5969,$A9,Games!$E$2:$E$5969)+SUMIF(Games!$B$2:$B$5969,$A9,Games!$F$2:$F$5969) -> 839 | J9: =SUMIF(Games!$A$2:$A$5969,$A9,Games!$F$2:$F$5969)+SUMIF(Games!$B$2:$B$5969,$A9,Games!$E$2:$E$5969) -> 1025 | K9: =SUMIF(Games!$A$2:$A$5969,$A9,Games!$G$2:$G$5969)+SUMIF(Games!$B$2:$B$5969,$A9,Games!$H$2:$H$5969) -> 391 | L9: =SUMIF(Games!$A$2:$A$5969,$A9,Games!$H$2:$H$5969)+SUMIF(Games!$B$2:$B$5969,$A9,Games!$G$2:$G$5969) -> 396 | M9: =SUMIF(Games!$A:$A,$A9,Games!I:I) -> 2 | N9: =COUNTIF(Games!$A:$A,$A9)-M9 -> 16 | O9: =I9-J9 -> -186 | P9: =IFERROR(O9/Y9,0) -> -6.4137931 | Q9: =L9-K9 -> 5 | R9: =IFERROR(Q9/Y9,0) -> 0.17241379 | S9: Patriot | T9: =IFERROR((B9/(B9+C9))*25,0)+IFERROR((D9/(D9+E9))*25,0)+IFERROR((F9/(F9+G9))*10,0)+H9+((P9-RDAVG)/RebSD)*10+((R9-TODAVG)/TOSD)*6 -> -46.848905 | U9: =W9*X9 -> 0.23590771 | V9: =RANK(U9,U$2:U$352) -> 305 | W9: =IFERROR((D9-C9)/(D9+E9-(B9+C9)),0) -> 0.47835498 | X9: =IFERROR((F9-((B9+C9)*B9))/((F9+G9)-(B9+C9)^2),0) -> 0.49316454 | Y9: =COUNTIFS(Games!$A$2:$A$5969,$A9,Games!$E$2:$E$5969,"<>")+COUNTIFS(Games!$B$2:$B$5969,$A9,Games!$F$2:$F$5969,"<>") -> 29
A10: App State | B10: =SUMIF(Games!$A$2:$A$5969,$A10,Games!$I$2:$I$5969)+SUMIF(Games!$B$2:$B$5969,$A10,Games!$J$2:$J$5969) -> 15 | C10: =COUNTIF(Games!$A:$A,$A10)+COUNTIF(Games!$B:$B,$A10)-B10 -> 18 | D10: =SUMIF(Games!$A$2:$A$5969,$A10,Games!$M$2:$M$5969)+SUMIF(Games!$B$2:$B$5969,$A10,Games!$K$2:$K$5969) -> 482 | E10: =SUMIF(Games!$A$2:$A$5969,$A10,Games!$N$2:$N$5969)+SUMIF(Games!$B$2:$B$5969,$A10,Games!$L$2:$L$5969) -> 535 | F10: =SUMIF(Games!$A$2:$A$5969,$A10,Games!$Q$2:$Q$5969)+SUMIF(Games!$B$2:$B$5969,$A10,Games!$O$2:$O$5969) -> 16627 | G10: =SUMIF(Games!$A$2:$A$5969,$A10,Games!$R$2:$R$5969)+SUMIF(Games!$B$2:$B$5969,$A10,Games!$P$2:$P$5969) -> 15346 | H10: =SUMIF(Games!$A$2:$A$5969,$A10,Games!$S$2:$S$5969)+SUMIF(Games!$B$2:$B$5969,$A10,Games!$T$2:$T$5969) -> -12.294756 | I10: =SUMIF(Games!$A$2:$A$5969,$A10,Games!$E$2:$E$5969)+SUMIF(Games!$B$2:$B$5969,$A10,Games!$F$2:$F$5969) -> 1291 | J10: =SUMIF(Games!$A$2:$A$5969,$A10,Games!$F$2:$F$5969)+SUMIF(Games!$B$2:$B$5969,$A10,Games!$E$2:$E$5969) -> 1178 | K10: =SUMIF(Games!$A$2:$A$5969,$A10,Games!$G$2:$G$5969)+SUMIF(Games!$B$2:$B$5969,$A10,Games!$H$2:$H$5969) -> 457 | L10: =SUMIF(Games!$A$2:$A$5969,$A10,Games!$H$2:$H$5969)+SUMIF(Games!$B$2:$B$5969,$A10,Games!$G$2:$G$5969) -> 430 | M10: =SUMIF(Games!$A:$A,$A10,Games!I:I) -> 4 | N10: =COUNTIF(Games!$A:$A,$A10)-M10 -> 13 | O10: =I10-J10 -> 113 | P10: =IFERROR(O10/Y10,0) -> 3.4242424 | Q10: =L10-K10 -> -27 | R10: =IFERROR(Q10/Y10,0) -> -0.81818182 | S10: Sun Belt | T10: =IFERROR((B10/(B10+C10))*25,0)+IFERROR((D10/(D10+E10))*25,0)+IFERROR((F10/(F10+G10))*10,0)+H10+((P10-RDAVG)/RebSD)*10+((R10-TODAVG)/TOSD)*6 -> 21.192514 | U10: =W10*X10 -> 0.24630745 | V10: =RANK(U10,U$2:U$352) -> 280 | W10: =IFERROR((D10-C10)/(D10+E10-(B10+C10)),0) -> 0.47154472 | X10: =IFERROR((F10-((B10+C10)*B10))/((F10+G10)-(B10+C10)^2),0) -> 0.52234167 | Y10: =COUNTIFS(Games!$A$2:$A$5969,$A10,Games!$E$2:$E$5969,"<>")+COUNTIFS(Games!$B$2:$B$5969,$A10,Games!$F$2:$F$5969,"<>") -> 33
